Workbook

Sheet cosecha
A1: Control de actividades diarias
A2: Labor | B2: Cosecha TOMATE
A3: Finca: | B3: Las Mesas
A4: Mes
E5: Días del mes
A6: Trabajador | B6: hrs | C6: CAJAS | D6: # tramos/h | E6: 1 | G6: 2 | I6: 3 | K6: 4 | M6: 5 | O6: 6 | Q6: 7 | S6: 8 | U6: 9 | W6: 10 | Y6: 11 | AA6: 12 | AC6: 13 | AE6: 14 | AG6: 15 | AI6: 16 | AK6: 17 | AM6: 18 | AO6: 19 | AQ6: 20 | AS6: 21 | AU6: 22 | AW6: 23 | AY6: 24 | BA6: 25 | BC6: 26 | BE6: 27 | BG6: 28 | BI6: 29 | BK6: 30 | BM6: 31
E7: Hrs | F7: CAJAS | G7: Hrs | H7: # tramos | I7: Hrs | J7: # tramos | K7: Hrs | L7: # tramos | M7: Hrs | N7: # tramos | O7: Hrs | P7: # tramos | Q7: Hrs | R7: # tramos | S7: Hrs | T7: # tramos | U7: Hrs | V7: # tramos | W7: Hrs | X7: # tramos | Y7: Hrs | Z7: # tramos | AA7: Hrs | AB7: # tramos | AC7: Hrs | AD7: # tramos | AE7: Hrs | AF7: # tramos | AG7: Hrs | AH7: # tramos | AI7: Hrs | AJ7: TINAS | AK7: Hrs | AL7: # tramos | AM7: Hrs | AN7: TINAS | AO7: Hrs | AP7: # tramos | AQ7: Hrs | AR7: TINAS | AS7: Hrs | AT7: # tramos | AU7: Hrs | AV7: # tramos | AW7: Hrs | AX7: TINAS | AY7: Hrs | AZ7: # tramos | BA7: Hrs | BB7: TINAS | BC7: Hrs | BD7: # tramos | BE7: Hrs | BF7: # tramos | BG7: Hrs | BH7: # tramos | BI7: Hrs | BJ7: # tramos | BK7: Hrs | BL7: # tramos | BM7: Hrs | BN7: # tramos
A8: WILMER ALTAMIRANO | B8: =+E8+G8+I8+K8+M8+O8+Q8+S8+U8+W8+Y8+AA8+AC8+AE8+AG8+AI8+AK8+AO8+AQ8+AS8+AU8+AW8+AY8+BA8+BC8+BE8+BG8+BI8+BK8+BM8 -> 4.1 | C8: 0 | D8: =+C8/B8 -> 0 | E8: 4.1 | F8: 26
A9: Jefry jardín | B9: =+E9+G9+I9+K9+M9+O9+Q9+S9+U9+W9+Y9+AA9+AC9+AE9+AG9+AI9+AK9+AO9+AQ9+AS9+AU9+AW9+AY9+BA9+BC9+BE9+BG9+BI9+BK9+BM9 -> 3 | C9: 0 | D9: =+C9/B9 -> 0 | E9: 3 | F9: 23
A10: JEFRAN POLANCO | B10: =+E10+G10+I10+K10+M10+O10+Q10+S10+U10+W10+Y10+AA10+AC10+AE10+AG10+AI10+AK10+AO10+AQ10+AS10+AU10+AW10+AY10+BA10+BC10+BE10+BG10+BI10+BK10+BM10 -> 4.1 | C10: 0 | D10: =+C10/B10 -> 0 | E10: 4.1 | F10: 28
A11: JUAN FIDENCIO | B11: =+E11+G11+I11+K11+M11+O11+Q11+S11+U11+W11+Y11+AA11+AC11+AE11+AG11+AI11+AK11+AO11+AQ11+AS11+AU11+AW11+AY11+BA11+BC11+BE11+BG11+BI11+BK11+BM11 -> 4.1 | C11: 0 | D11: =+C11/B11 -> 0 | E11: 4.1 | F11: 29
A12: HECTOR DÍAS | B12: =+E12+G12+I12+K12+M12+O12+Q12+S12+U12+W12+Y12+AA12+AC12+AE12+AG12+AI12+AK12+AO12+AQ12+AS12+AU12+AW12+AY12+BA12+BC12+BE12+BG12+BI12+BK12+BM12 -> 4.1 | C12: 0 | D12: =+C12/B12 -> 0 | E12: 4.1 | F12: 32
A13: MAYNOR AGUILAR | B13: =+E13+G13+I13+K13+M13+O13+Q13+S13+U13+W13+Y13+AA13+AC13+AE13+AG13+AI13+AK13+AO13+AQ13+AS13+AU13+AW13+AY13+BA13+BC13+BE13+BG13+BI13+BK13+BM13 -> 4.1 | C13: 0 | D13: =+C13/B13 -> 0 | E13: 4.1 | F13: 31
A14: HAXEL ZUAREZ | B14: =+E14+G14+I14+K14+M14+O14+Q14+S14+U14+W14+Y14+AA14+AC14+AE14+AG14+AI14+AK14+AO14+AQ14+AS14+AU14+AW14+AY14+BA14+BC14+BE14+BG14+BI14+BK14+BM14 -> 4.1 | C14: 0 | D14: =+C14/B14 -> 0 | E14: 4.1 | F14: 30
A15: MARVEN JARQUIN | B15: =+E15+G15+I15+K15+M15+O15+Q15+S15+U15+W15+Y15+AA15+AC15+AE15+AG15+AI15+AK15+AO15+AQ15+AS15+AU15+AW15+AY15+BA15+BC15+BE15+BG15+BI15+BK15+BM15 -> 4.1 | C15: 0 | D15: =+C15/B15 -> 0 | E15: 4.1 | F15: 33
A16: OSCAR AGUILAR | B16: =+E16+G16+I16+K16+M16+O16+Q16+S16+U16+W16+Y16+AA16+AC16+AE16+AG16+AI16+AK16+AO16+AQ16+AS16+AU16+AW16+AY16+BA16+BC16+BE16+BG16+BI16+BK16+BM16 -> 4.1 | C16: 0 | D16: =+C16/B16 -> 0 | E16: 4.1 | F16: 29
A17: MARLON LOPEZ | B17: =+E17+G17+I17+K17+M17+O17+Q17+S17+U17+W17+Y17+AA17+AC17+AE17+AG17+AI17+AK17+AO17+AQ17+AS17+AU17+AW17+AY17+BA17+BC17+BE17+BG17+BI17+BK17+BM17 -> 4.1 | C17: 0 | D17: =+C17/B17 -> 0 | E17: 4.1 | F17: 26
A18: DEIVIN TERCERO | B18: =+E18+G18+I18+K18+M18+O18+Q18+S18+U18+W18+Y18+AA18+AC18+AE18+AG18+AI18+AK18+AO18+AQ18+AS18+AU18+AW18+AY18+BA18+BC18+BE18+BG18+BI18+BK18+BM18 -> 4.1 | C18: 0 | D18: =+C18/B18 -> 0 | E18: 4.1 | F18: 29
A19: ELYAZAR TERCERO | B19: =+E19+G19+I19+K19+M19+O19+Q19+S19+U19+W19+Y19+AA19+AC19+AE19+AG19+AI19+AK19+AO19+AQ19+AS19+AU19+AW19+AY19+BA19+BC19+BE19+BG19+BI19+BK19+BM19 -> 4.1 | C19: 0 | D19: =+C19/B19 -> 0 | E19: 4.1 | F19: 35
B20: 0 | C20: 0 | D20: =+C20/B20 -> #DIV/0!
B21: =+E21+G21+I21+K21+M21+O21+Q21+S21+U21+W21+Y21+AA21+AC21+AE21+AG21+AI21+AK21+AO21+AQ21+AS21+AU21+AW21+AY21+BA21+BC21+BE21+BG21+BI21+BK21+BM21 -> 0 | C21: 0 | D21: =+C21/B21 -> #DIV/0!
B22: =+E22+G22+I22+K22+M22+O22+Q22+S22+U22+W22+Y22+AA22+AC22+AE22+AG22+AI22+AK22+AO22+AQ22+AS22+AU22+AW22+AY22+BA22+BC22+BE22+BG22+BI22+BK22+BM22 -> 0 | C22: 0 | D22: =+C22/B22 -> #DIV/0!
B23: =+E23+G23+I23+K23+M23+O23+Q23+S23+U23+W23+Y23+AA23+AC23+AE23+AG23+AI23+AK23+AO23+AQ23+AS23+AU23+AW23+AY23+BA23+BC23+BE23+BG23+BI23+BK23+BM23 -> 0 | C23: 0 | D23: =+C23/B23 -> #DIV/0!
B24: =+E24+G24+I24+K24+M24+O24+Q24+S24+U24+W24+Y24+AA24+AC24+AE24+AG24+AI24+AK24+AO24+AQ24+AS24+AU24+AW24+AY24+BA24+BC24+BE24+BG24+BI24+BK24+BM24 -> 0 | C24: 0 | D24: =+C24/B24 -> #DIV/0!
B25: =+E25+G25+I25+K25+M25+O25+Q25+S25+U25+W25+Y25+AA25+AC25+AE25+AG25+AI25+AK25+AO25+AQ25+AS25+AU25+AW25+AY25+BA25+BC25+BE25+BG25+BI25+BK25+BM25 -> 0 | C25: 0 | D25: =+C25/B25 -> #DIV/0!
B26: 0 | C26: 0 | D26: =+C26/B26 -> #DIV/0!
B27: =+E27+G27+I27+K27+M27+O27+Q27+S27+U27+W27+Y27+AA27+AC27+AE27+AG27+AI27+AK27+AO27+AQ27+AS27+AU27+AW27+AY27+BA27+BC27+BE27+BG27+BI27+BK27+BM27 -> 0 | C27: 0 | D27: =+C27/B27 -> #DIV/0!
B28: =+E28+G28+I28+K28+M28+O28+Q28+S28+U28+W28+Y28+AA28+AC28+AE28+AG28+AI28+AK28+AO28+AQ28+AS28+AU28+AW28+AY28+BA28+BC28+BE28+BG28+BI28+BK28+BM28 -> 0 | C28: =+F28+H28+J28+L28+N28+P28+R28+T28+V28+X28+Z28+AB28+AD28+AF28+AH28+AJ28+AL28+AP28+AR28+AT28+AV28+AX28+AZ28+BB28+BD28+BF28+BH28+BJ28+BL28+BN28 -> 0 | D28: =+C28/B28 -> #DIV/0!
B29: =+E29+G29+I29+K29+M29+O29+Q29+S29+U29+W29+Y29+AA29+AC29+AE29+AG29+AI29+AK29+AO29+AQ29+AS29+AU29+AW29+AY29+BA29+BC29+BE29+BG29+BI29+BK29+BM29 -> 0 | C29: =+F29+H29+J29+L29+N29+P29+R29+T29+V29+X29+Z29+AB29+AD29+AF29+AH29+AJ29+AL29+AP29+AR29+AT29+AV29+AX29+AZ29+BB29+BD29+BF29+BH29+BJ29+BL29+BN29 -> 0 | D29: =+C29/B29 -> #DIV/0!
B30: =+E30+G30+I30+K30+M30+O30+Q30+S30+U30+W30+Y30+AA30+AC30+AE30+AG30+AI30+AK30+AO30+AQ30+AS30+AU30+AW30+AY30+BA30+BC30+BE30+BG30+BI30+BK30+BM30 -> 0 | C30: =+F30+H30+J30+L30+N30+P30+R30+T30+V30+X30+Z30+AB30+AD30+AF30+AH30+AJ30+AL30+AP30+AR30+AT30+AV30+AX30+AZ30+BB30+BD30+BF30+BH30+BJ30+BL30+BN30 -> 0 | D30: =+C30/B30 -> #DIV/0!
B31: 0 | C31: 0 | D31: =+C31/B31 -> #DIV/0!
B32: 0 | C32: 0 | D32: =+C32/B32 -> #DIV/0!
B33: =+E33+G33+I33+K33+M33+O33+Q33+S33+U33+W33+Y33+AA33+AC33+AE33+AG33+AI33+AK33+AO33+AQ33+AS33+AU33+AW33+AY33+BA33+BC33+BE33+BG33+BI33+BK33+BM33 -> 0 | C33: =+F33+H33+J33+L33+N33+P33+R33+T33+V33+X33+Z33+AB33+AD33+AF33+AH33+AJ33+AL33+AP33+AR33+AT33+AV33+AX33+AZ33+BB33+BD33+BF33+BH33+BJ33+BL33+BN33 -> 0 | D33: =+C33/B33 -> #DIV/0!
B34: =+E34+G34+I34+K34+M34+O34+Q34+S34+U34+W34+Y34+AA34+AC34+AE34+AG34+AI34+AK34+AO34+AQ34+AS34+AU34+AW34+AY34+BA34+BC34+BE34+BG34+BI34+BK34+BM34 -> 0 | C34: =+F34+H34+J34+L34+N34+P34+R34+T34+V34+X34+Z34+AB34+AD34+AF34+AH34+AJ34+AL34+AP34+AR34+AT34+AV34+AX34+AZ34+BB34+BD34+BF34+BH34+BJ34+BL34+BN34 -> 0 | D34: =+C34/B34 -> #DIV/0!
B35: =+E35+G35+I35+K35+M35+O35+Q35+S35+U35+W35+Y35+AA35+AC35+AE35+AG35+AI35+AK35+AO35+AQ35+AS35+AU35+AW35+AY35+BA35+BC35+BE35+BG35+BI35+BK35+BM35 -> 0 | C35: =+F35+H35+J35+L35+N35+P35+R35+T35+V35+X35+Z35+AB35+AD35+AF35+AH35+AJ35+AL35+AP35+AR35+AT35+AV35+AX35+AZ35+BB35+BD35+BF35+BH35+BJ35+BL35+BN35 -> 0 | D35: =+C35/B35 -> #DIV/0!
B36: =+E36+G36+I36+K36+M36+O36+Q36+S36+U36+W36+Y36+AA36+AC36+AE36+AG36+AI36+AK36+AO36+AQ36+AS36+AU36+AW36+AY36+BA36+BC36+BE36+BG36+BI36+BK36+BM36 -> 0 | C36: =+F36+H36+J36+L36+N36+P36+R36+T36+V36+X36+Z36+AB36+AD36+AF36+AH36+AJ36+AL36+AP36+AR36+AT36+AV36+AX36+AZ36+BB36+BD36+BF36+BH36+BJ36+BL36+BN36 -> 0 | D36: =+C36/B36 -> #DIV/0!
B37: =+E37+G37+I37+K37+M37+O37+Q37+S37+U37+W37+Y37+AA37+AC37+AE37+AG37+AI37+AK37+AO37+AQ37+AS37+AU37+AW37+AY37+BA37+BC37+BE37+BG37+BI37+BK37+BM37 -> 0 | C37: =+F37+H37+J37+L37+N37+P37+R37+T37+V37+X37+Z37+AB37+AD37+AF37+AH37+AJ37+AL37+AP37+AR37+AT37+AV37+AX37+AZ37+BB37+BD37+BF37+BH37+BJ37+BL37+BN37 -> 0 | D37: =+C37/B37 -> #DIV/0!
B38: =+E38+G38+I38+K38+M38+O38+Q38+S38+U38+W38+Y38+AA38+AC38+AE38+AG38+AI38+AK38+AO38+AQ38+AS38+AU38+AW38+AY38+BA38+BC38+BE38+BG38+BI38+BK38+BM38 -> 0 | C38: =+F38+H38+J38+L38+N38+P38+R38+T38+V38+X38+Z38+AB38+AD38+AF38+AH38+AJ38+AL38+AP38+AR38+AT38+AV38+AX38+AZ38+BB38+BD38+BF38+BH38+BJ38+BL38+BN38 -> 0 | D38: =+C38/B38 -> #DIV/0!
B39: =+E39+G39+I39+K39+M39+O39+Q39+S39+U39+W39+Y39+AA39+AC39+AE39+AG39+AI39+AK39+AO39+AQ39+AS39+AU39+AW39+AY39+BA39+BC39+BE39+BG39+BI39+BK39+BM39 -> 0 | C39: =+F39+H39+J39+L39+N39+P39+R39+T39+V39+X39+Z39+AB39+AD39+AF39+AH39+AJ39+AL39+AP39+AR39+AT39+AV39+AX39+AZ39+BB39+BD39+BF39+BH39+BJ39+BL39+BN39 -> 0 | D39: =+C39/B39 -> #DIV/0!
B40: =+E40+G40+I40+K40+M40+O40+Q40+S40+U40+W40+Y40+AA40+AC40+AE40+AG40+AI40+AK40+AO40+AQ40+AS40+AU40+AW40+AY40+BA40+BC40+BE40+BG40+BI40+BK40+BM40 -> 0 | C40: =+F40+H40+J40+L40+N40+P40+R40+T40+V40+X40+Z40+AB40+AD40+AF40+AH40+AJ40+AL40+AP40+AR40+AT40+AV40+AX40+AZ40+BB40+BD40+BF40+BH40+BJ40+BL40+BN40 -> 0 | D40: =+C40/B40 -> #DIV/0!
...

Sheet amarre 1
A1: Control de actividades diarias
A2: Labor | B2: AMARRE 1
A3: Finca: | B3: =+cosecha!B3 -> Las Mesas
A4: Mes | B4: =+cosecha!B4
E5: Días del mes
A6: Trabajador | B6: hrs | C6: # tramos | D6: # tramos/h | E6: 1 | G6: 2 | I6: 3 | K6: 4 | M6: 5 | O6: 6 | Q6: 7 | S6: 8 | U6: 9 | W6: 10 | Y6: 11 | AA6: 12 | AC6: 13 | AE6: 14 | AG6: 15 | AI6: 16 | AK6: 17 | AM6: 18 | AO6: 19 | AQ6: 20 | AS6: 21 | AU6: 22 | AW6: 23 | AY6: 24 | BA6: 25 | BC6: 26 | BE6: 27 | BG6: 28 | BI6: 29 | BK6: 30 | BM6: 31
E7: Hrs | F7: # tramos | G7: Hrs | H7: # tramos | I7: Hrs | J7: # tramos | K7: Hrs | L7: # tramos | M7: Hrs | N7: # tramos | O7: Hrs | P7: # tramos | Q7: Hrs | R7: # tramos | S7: Hrs | T7: # tramos | U7: Hrs | V7: # tramos | W7: Hrs | X7: # tramos | Y7: Hrs | Z7: # tramos | AA7: Hrs | AB7: # tramos | AC7: Hrs | AD7: # tramos | AE7: Hrs | AF7: # tramos | AG7: Hrs | AH7: # tramos | AI7: Hrs | AJ7: # tramos | AK7: Hrs | AL7: # tramos | AM7: Hrs | AN7: # tramos | AO7: Hrs | AP7: # tramos | AQ7: Hrs | AR7: # tramos | AS7: Hrs | AT7: # tramos | AU7: Hrs | AV7: # tramos | AW7: Hrs | AX7: # tramos | AY7: Hrs | AZ7: # tramos | BA7: Hrs | BB7: # tramos | BC7: Hrs | BD7: # tramos | BE7: Hrs | BF7: # tramos | BG7: Hrs | BH7: # tramos | BI7: Hrs | BJ7: # tramos | BK7: Hrs | BL7: # tramos | BM7: Hrs | BN7: # tramos
A8: ALONZO LOZA | B8: =+E8+G8+I8+K8+M8+O8+Q8+S8+U8+W8+Y8+AA8+AC8+AE8+AG8+AI8+AK8+AO8+AQ8+AS8+AU8+AW8+AY8+BA8+BC8+BE8+BG8+BI8+BK8+BM8 -> 0 | C8: =+F8+H8+J8+L8+N8+P8+R8+T8+V8+X8+Z8+AB8+AD8+AF8+AH8+AJ8+AL8+AP8+AR8+AT8+AV8+AX8+AZ8+BB8+BD8+BF8+BH8+BJ8+BL8+BN8 -> 0 | D8: =+C8/B8 -> #DIV/0!
A9: ALVIN ALCANTARA | B9: =+E9+G9+I9+K9+M9+O9+Q9+S9+U9+W9+Y9+AA9+AC9+AE9+AG9+AI9+AK9+AO9+AQ9+AS9+AU9+AW9+AY9+BA9+BC9+BE9+BG9+BI9+BK9+BM9 -> 0 | C9: =+F9+H9+J9+L9+N9+P9+R9+T9+V9+X9+Z9+AB9+AD9+AF9+AH9+AJ9+AL9+AP9+AR9+AT9+AV9+AX9+AZ9+BB9+BD9+BF9+BH9+BJ9+BL9+BN9 -> 0 | D9: =+C9/B9 -> #DIV/0!
A10: BILOMAR URBINA | B10: =+E10+G10+I10+K10+M10+O10+Q10+S10+U10+W10+Y10+AA10+AC10+AE10+AG10+AI10+AK10+AO10+AQ10+AS10+AU10+AW10+AY10+BA10+BC10+BE10+BG10+BI10+BK10+BM10 -> 0 | C10: =+F10+H10+J10+L10+N10+P10+R10+T10+V10+X10+Z10+AB10+AD10+AF10+AH10+AJ10+AL10+AP10+AR10+AT10+AV10+AX10+AZ10+BB10+BD10+BF10+BH10+BJ10+BL10+BN10 -> 0 | D10: =+C10/B10 -> #DIV/0!
A11: CARLOS ANTHONIO JIMENEZ | B11: =+E11+G11+I11+K11+M11+O11+Q11+S11+U11+W11+Y11+AA11+AC11+AE11+AG11+AI11+AK11+AO11+AQ11+AS11+AU11+AW11+AY11+BA11+BC11+BE11+BG11+BI11+BK11+BM11 -> 0 | C11: =+F11+H11+J11+L11+N11+P11+R11+T11+V11+X11+Z11+AB11+AD11+AF11+AH11+AJ11+AL11+AP11+AR11+AT11+AV11+AX11+AZ11+BB11+BD11+BF11+BH11+BJ11+BL11+BN11 -> 0 | D11: =+C11/B11 -> #DIV/0!
A12: CESAR POLANCO | B12: =+E12+G12+I12+K12+M12+O12+Q12+S12+U12+W12+Y12+AA12+AC12+AE12+AG12+AI12+AK12+AO12+AQ12+AS12+AU12+AW12+AY12+BA12+BC12+BE12+BG12+BI12+BK12+BM12 -> 0 | C12: =+F12+H12+J12+L12+N12+P12+R12+T12+V12+X12+Z12+AB12+AD12+AF12+AH12+AJ12+AL12+AP12+AR12+AT12+AV12+AX12+AZ12+BB12+BD12+BF12+BH12+BJ12+BL12+BN12 -> 0 | D12: =+C12/B12 -> #DIV/0!
A13: ELVIN GARCIA ROSTRAON | B13: =+E13+G13+I13+K13+M13+O13+Q13+S13+U13+W13+Y13+AA13+AC13+AE13+AG13+AI13+AK13+AO13+AQ13+AS13+AU13+AW13+AY13+BA13+BC13+BE13+BG13+BI13+BK13+BM13 -> 0 | C13: =+F13+H13+J13+L13+N13+P13+R13+T13+V13+X13+Z13+AB13+AD13+AF13+AH13+AJ13+AL13+AP13+AR13+AT13+AV13+AX13+AZ13+BB13+BD13+BF13+BH13+BJ13+BL13+BN13 -> 0 | D13: =+C13/B13 -> #DIV/0!
A14: ELVIS FLORES | B14: =+E14+G14+I14+K14+M14+O14+Q14+S14+U14+W14+Y14+AA14+AC14+AE14+AG14+AI14+AK14+AO14+AQ14+AS14+AU14+AW14+AY14+BA14+BC14+BE14+BG14+BI14+BK14+BM14 -> 0 | C14: =+F14+H14+J14+L14+N14+P14+R14+T14+V14+X14+Z14+AB14+AD14+AF14+AH14+AJ14+AL14+AP14+AR14+AT14+AV14+AX14+AZ14+BB14+BD14+BF14+BH14+BJ14+BL14+BN14 -> 0 | D14: =+C14/B14 -> #DIV/0!
A15: GABRIEL VEGA | B15: =+E15+G15+I15+K15+M15+O15+Q15+S15+U15+W15+Y15+AA15+AC15+AE15+AG15+AI15+AK15+AO15+AQ15+AS15+AU15+AW15+AY15+BA15+BC15+BE15+BG15+BI15+BK15+BM15 -> 0 | C15: =+F15+H15+J15+L15+N15+P15+R15+T15+V15+X15+Z15+AB15+AD15+AF15+AH15+AJ15+AL15+AP15+AR15+AT15+AV15+AX15+AZ15+BB15+BD15+BF15+BH15+BJ15+BL15+BN15 -> 0 | D15: =+C15/B15 -> #DIV/0!
A16: HOLLMAN ZAPATA | B16: =+E16+G16+I16+K16+M16+O16+Q16+S16+U16+W16+Y16+AA16+AC16+AE16+AG16+AI16+AK16+AO16+AQ16+AS16+AU16+AW16+AY16+BA16+BC16+BE16+BG16+BI16+BK16+BM16 -> 0 | C16: =+F16+H16+J16+L16+N16+P16+R16+T16+V16+X16+Z16+AB16+AD16+AF16+AH16+AJ16+AL16+AP16+AR16+AT16+AV16+AX16+AZ16+BB16+BD16+BF16+BH16+BJ16+BL16+BN16 -> 0 | D16: =+C16/B16 -> #DIV/0!
A17: JOSE ANTONIO VAZQUEZ | B17: =+E17+G17+I17+K17+M17+O17+Q17+S17+U17+W17+Y17+AA17+AC17+AE17+AG17+AI17+AK17+AO17+AQ17+AS17+AU17+AW17+AY17+BA17+BC17+BE17+BG17+BI17+BK17+BM17 -> 0 | C17: =+F17+H17+J17+L17+N17+P17+R17+T17+V17+X17+Z17+AB17+AD17+AF17+AH17+AJ17+AL17+AP17+AR17+AT17+AV17+AX17+AZ17+BB17+BD17+BF17+BH17+BJ17+BL17+BN17 -> 0 | D17: =+C17/B17 -> #DIV/0!
A18: JOSE DAMIEL LOZA | B18: =+E18+G18+I18+K18+M18+O18+Q18+S18+U18+W18+Y18+AA18+AC18+AE18+AG18+AI18+AK18+AO18+AQ18+AS18+AU18+AW18+AY18+BA18+BC18+BE18+BG18+BI18+BK18+BM18 -> 0 | C18: =+F18+H18+J18+L18+N18+P18+R18+T18+V18+X18+Z18+AB18+AD18+AF18+AH18+AJ18+AL18+AP18+AR18+AT18+AV18+AX18+AZ18+BB18+BD18+BF18+BH18+BJ18+BL18+BN18 -> 0 | D18: =+C18/B18 -> #DIV/0!
A19: JOSE DENIS PASTRAN | B19: =+E19+G19+I19+K19+M19+O19+Q19+S19+U19+W19+Y19+AA19+AC19+AE19+AG19+AI19+AK19+AO19+AQ19+AS19+AU19+AW19+AY19+BA19+BC19+BE19+BG19+BI19+BK19+BM19 -> 0 | C19: =+F19+H19+J19+L19+N19+P19+R19+T19+V19+X19+Z19+AB19+AD19+AF19+AH19+AJ19+AL19+AP19+AR19+AT19+AV19+AX19+AZ19+BB19+BD19+BF19+BH19+BJ19+BL19+BN19 -> 0 | D19: =+C19/B19 -> #DIV/0!
... A31: SERGIO GUZMAN | B31: =+E31+G31+I31+K31+M31+O31+Q31+S31+U31+W31+Y31+AA31+AC31+AE31+AG31+AI31+AK31+AO31+AQ31+AS31+AU31+AW31+AY31+BA31+BC31+BE31+BG31+BI31+BK31+BM31 -> 0 | C31: =+F31+H31+J31+L31+N31+P31+R31+T31+V31+X31+Z31+AB31+AD31+AF31+AH31+AJ31+AL31+AP31+AR31+AT31+AV31+AX31+AZ31+BB31+BD31+BF31+BH31+BJ31+BL31+BN31 -> 0 | D31: =+C31/B31 -> #DIV/0!
A32: YERIL MANUEL ZAPATA
B33: =+E33+G33+I33+K33+M33+O33+Q33+S33+U33+W33+Y33+AA33+AC33+AE33+AG33+AI33+AK33+AO33+AQ33+AS33+AU33+AW33+AY33+BA33+BC33+BE33+BG33+BI33+BK33+BM33 -> 0 | C33: =+F33+H33+J33+L33+N33+P33+R33+T33+V33+X33+Z33+AB33+AD33+AF33+AH33+AJ33+AL33+AP33+AR33+AT33+AV33+AX33+AZ33+BB33+BD33+BF33+BH33+BJ33+BL33+BN33 -> 0 | D33: =+C33/B33 -> #DIV/0!
B34: =+E34+G34+I34+K34+M34+O34+Q34+S34+U34+W34+Y34+AA34+AC34+AE34+AG34+AI34+AK34+AO34+AQ34+AS34+AU34+AW34+AY34+BA34+BC34+BE34+BG34+BI34+BK34+BM34 -> 0 | C34: =+F34+H34+J34+L34+N34+P34+R34+T34+V34+X34+Z34+AB34+AD34+AF34+AH34+AJ34+AL34+AP34+AR34+AT34+AV34+AX34+AZ34+BB34+BD34+BF34+BH34+BJ34+BL34+BN34 -> 0 | D34: =+C34/B34 -> #DIV/0!
B35: =+E35+G35+I35+K35+M35+O35+Q35+S35+U35+W35+Y35+AA35+AC35+AE35+AG35+AI35+AK35+AO35+AQ35+AS35+AU35+AW35+AY35+BA35+BC35+BE35+BG35+BI35+BK35+BM35 -> 0 | C35: =+F35+H35+J35+L35+N35+P35+R35+T35+V35+X35+Z35+AB35+AD35+AF35+AH35+AJ35+AL35+AP35+AR35+AT35+AV35+AX35+AZ35+BB35+BD35+BF35+BH35+BJ35+BL35+BN35 -> 0 | D35: =+C35/B35 -> #DIV/0!
B36: =+E36+G36+I36+K36+M36+O36+Q36+S36+U36+W36+Y36+AA36+AC36+AE36+AG36+AI36+AK36+AO36+AQ36+AS36+AU36+AW36+AY36+BA36+BC36+BE36+BG36+BI36+BK36+BM36 -> 0 | C36: =+F36+H36+J36+L36+N36+P36+R36+T36+V36+X36+Z36+AB36+AD36+AF36+AH36+AJ36+AL36+AP36+AR36+AT36+AV36+AX36+AZ36+BB36+BD36+BF36+BH36+BJ36+BL36+BN36 -> 0 | D36: =+C36/B36 -> #DIV/0!
B37: =+E37+G37+I37+K37+M37+O37+Q37+S37+U37+W37+Y37+AA37+AC37+AE37+AG37+AI37+AK37+AO37+AQ37+AS37+AU37+AW37+AY37+BA37+BC37+BE37+BG37+BI37+BK37+BM37 -> 0 | C37: =+F37+H37+J37+L37+N37+P37+R37+T37+V37+X37+Z37+AB37+AD37+AF37+AH37+AJ37+AL37+AP37+AR37+AT37+AV37+AX37+AZ37+BB37+BD37+BF37+BH37+BJ37+BL37+BN37 -> 0 | D37: =+C37/B37 -> #DIV/0!
B38: =+E38+G38+I38+K38+M38+O38+Q38+S38+U38+W38+Y38+AA38+AC38+AE38+AG38+AI38+AK38+AO38+AQ38+AS38+AU38+AW38+AY38+BA38+BC38+BE38+BG38+BI38+BK38+BM38 -> 0 | C38: =+F38+H38+J38+L38+N38+P38+R38+T38+V38+X38+Z38+AB38+AD38+AF38+AH38+AJ38+AL38+AP38+AR38+AT38+AV38+AX38+AZ38+BB38+BD38+BF38+BH38+BJ38+BL38+BN38 -> 0 | D38: =+C38/B38 -> #DIV/0!
B39: =+E39+G39+I39+K39+M39+O39+Q39+S39+U39+W39+Y39+AA39+AC39+AE39+AG39+AI39+AK39+AO39+AQ39+AS39+AU39+AW39+AY39+BA39+BC39+BE39+BG39+BI39+BK39+BM39 -> 0 | C39: =+F39+H39+J39+L39+N39+P39+R39+T39+V39+X39+Z39+AB39+AD39+AF39+AH39+AJ39+AL39+AP39+AR39+AT39+AV39+AX39+AZ39+BB39+BD39+BF39+BH39+BJ39+BL39+BN39 -> 0 | D39: =+C39/B39 -> #DIV/0!
B40: =+E40+G40+I40+K40+M40+O40+Q40+S40+U40+W40+Y40+AA40+AC40+AE40+AG40+AI40+AK40+AO40+AQ40+AS40+AU40+AW40+AY40+BA40+BC40+BE40+BG40+BI40+BK40+BM40 -> 0 | C40: =+F40+H40+J40+L40+N40+P40+R40+T40+V40+X40+Z40+AB40+AD40+AF40+AH40+AJ40+AL40+AP40+AR40+AT40+AV40+AX40+AZ40+BB40+BD40+BF40+BH40+BJ40+BL40+BN40 -> 0 | D40: =+C40/B40 -> #DIV/0!
B41: =+E41+G41+I41+K41+M41+O41+Q41+S41+U41+W41+Y41+AA41+AC41+AE41+AG41+AI41+AK41+AO41+AQ41+AS41+AU41+AW41+AY41+BA41+BC41+BE41+BG41+BI41+BK41+BM41 -> 0 | C41: =+F41+H41+J41+L41+N41+P41+R41+T41+V41+X41+Z41+AB41+AD41+AF41+AH41+AJ41+AL41+AP41+AR41+AT41+AV41+AX41+AZ41+BB41+BD41+BF41+BH41+BJ41+BL41+BN41 -> 0 | D41: =+C41/B41 -> #DIV/0!
B42: =+E42+G42+I42+K42+M42+O42+Q42+S42+U42+W42+Y42+AA42+AC42+AE42+AG42+AI42+AK42+AO42+AQ42+AS42+AU42+AW42+AY42+BA42+BC42+BE42+BG42+BI42+BK42+BM42 -> 0 | C42: =+F42+H42+J42+L42+N42+P42+R42+T42+V42+X42+Z42+AB42+AD42+AF42+AH42+AJ42+AL42+AP42+AR42+AT42+AV42+AX42+AZ42+BB42+BD42+BF42+BH42+BJ42+BL42+BN42 -> 0 | D42: =+C42/B42 -> #DIV/0!
B43: =+E43+G43+I43+K43+M43+O43+Q43+S43+U43+W43+Y43+AA43+AC43+AE43+AG43+AI43+AK43+AO43+AQ43+AS43+AU43+AW43+AY43+BA43+BC43+BE43+BG43+BI43+BK43+BM43 -> 0 | C43: =+F43+H43+J43+L43+N43+P43+R43+T43+V43+X43+Z43+AB43+AD43+AF43+AH43+AJ43+AL43+AP43+AR43+AT43+AV43+AX43+AZ43+BB43+BD43+BF43+BH43+BJ43+BL43+BN43 -> 0 | D43: =+C43/B43 -> #DIV/0!
B44: =+E44+G44+I44+K44+M44+O44+Q44+S44+U44+W44+Y44+AA44+AC44+AE44+AG44+AI44+AK44+AO44+AQ44+AS44+AU44+AW44+AY44+BA44+BC44+BE44+BG44+BI44+BK44+BM44 -> 0 | C44: =+F44+H44+J44+L44+N44+P44+R44+T44+V44+X44+Z44+AB44+AD44+AF44+AH44+AJ44+AL44+AP44+AR44+AT44+AV44+AX44+AZ44+BB44+BD44+BF44+BH44+BJ44+BL44+BN44 -> 0 | D44: =+C44/B44 -> #DIV/0!
... B50: =+E50+G50+I50+K50+M50+O50+Q50+S50+U50+W50+Y50+AA50+AC50+AE50+AG50+AI50+AK50+AO50+AQ50+AS50+AU50+AW50+AY50+BA50+BC50+BE50+BG50+BI50+BK50+BM50 -> 0 | C50: =+F50+H50+J50+L50+N50+P50+R50+T50+V50+X50+Z50+AB50+AD50+AF50+AH50+AJ50+AL50+AP50+AR50+AT50+AV50+AX50+AZ50+BB50+BD50+BF50+BH50+BJ50+BL50+BN50 -> 0 | D50: =+C50/B50 -> #DIV/0!

Sheet amarre 2
A1: Control de actividades diarias
A2: Labor | B2: AMARRE 2
A3: Finca: | B3: =+'amarre 1'!B3 -> Las Mesas
A4: Mes | B4: =+'amarre 1'!B4
E5: Días del mes
A6: Trabajador | B6: hrs | C6: # tramos | D6: # tramos/h | E6: 1 | G6: 2 | I6: 3 | K6: 4 | M6: 5 | O6: 6 | Q6: 7 | S6: 8 | U6: 9 | W6: 10 | Y6: 11 | AA6: 12 | AC6: 13 | AE6: 14 | AG6: 15 | AI6: 16 | AK6: 17 | AM6: 18 | AO6: 19 | AQ6: 20 | AS6: 21 | AU6: 22 | AW6: 23 | AY6: 24 | BA6: 25 | BC6: 26 | BE6: 27 | BG6: 28 | BI6: 29 | BK6: 30 | BM6: 31
E7: Hrs | F7: # tramos | G7: Hrs | H7: # tramos | I7: Hrs | J7: # tramos | K7: Hrs | L7: # tramos | M7: Hrs | N7: # tramos | O7: Hrs | P7: # tramos | Q7: Hrs | R7: # tramos | S7: Hrs | T7: # tramos | U7: Hrs | V7: # tramos | W7: Hrs | X7: # tramos | Y7: Hrs | Z7: # tramos | AA7: Hrs | AB7: # tramos | AC7: Hrs | AD7: # tramos | AE7: Hrs | AF7: # tramos | AG7: Hrs | AH7: # tramos | AI7: Hrs | AJ7: # tramos | AK7: Hrs | AL7: # tramos | AM7: Hrs | AN7: # tramos | AO7: Hrs | AP7: # tramos | AQ7: Hrs | AR7: # tramos | AS7: Hrs | AT7: # tramos | AU7: Hrs | AV7: # tramos | AW7: Hrs | AX7: # tramos | AY7: Hrs | AZ7: # tramos | BA7: Hrs | BB7: # tramos | BC7: Hrs | BD7: # tramos | BE7: Hrs | BF7: # tramos | BG7: Hrs | BH7: # tramos | BI7: Hrs | BJ7: # tramos | BK7: Hrs | BL7: # tramos | BM7: Hrs | BN7: # tramos
A8: ALONZO LOZA | B8: =+E8+G8+I8+K8+M8+O8+Q8+S8+U8+W8+Y8+AA8+AC8+AE8+AG8+AI8+AK8+AO8+AQ8+AS8+AU8+AW8+AY8+BA8+BC8+BE8+BG8+BI8+BK8+BM8 -> 0 | C8: =+F8+H8+J8+L8+N8+P8+R8+T8+V8+X8+Z8+AB8+AD8+AF8+AH8+AJ8+AL8+AP8+AR8+AT8+AV8+AX8+AZ8+BB8+BD8+BF8+BH8+BJ8+BL8+BN8 -> 0 | D8: =+C8/B8 -> #DIV/0!
A9: ALVIN ALCANTARA | B9: =+E9+G9+I9+K9+M9+O9+Q9+S9+U9+W9+Y9+AA9+AC9+AE9+AG9+AI9+AK9+AO9+AQ9+AS9+AU9+AW9+AY9+BA9+BC9+BE9+BG9+BI9+BK9+BM9 -> 0 | C9: =+F9+H9+J9+L9+N9+P9+R9+T9+V9+X9+Z9+AB9+AD9+AF9+AH9+AJ9+AL9+AP9+AR9+AT9+AV9+AX9+AZ9+BB9+BD9+BF9+BH9+BJ9+BL9+BN9 -> 0 | D9: =+C9/B9 -> #DIV/0!
A10: BILOMAR URBINA | B10: =+E10+G10+I10+K10+M10+O10+Q10+S10+U10+W10+Y10+AA10+AC10+AE10+AG10+AI10+AK10+AO10+AQ10+AS10+AU10+AW10+AY10+BA10+BC10+BE10+BG10+BI10+BK10+BM10 -> 0 | C10: =+F10+H10+J10+L10+N10+P10+R10+T10+V10+X10+Z10+AB10+AD10+AF10+AH10+AJ10+AL10+AP10+AR10+AT10+AV10+AX10+AZ10+BB10+BD10+BF10+BH10+BJ10+BL10+BN10 -> 0 | D10: =+C10/B10 -> #DIV/0!
A11: CARLOS ANTHONIO JIMENEZ | B11: =+E11+G11+I11+K11+M11+O11+Q11+S11+U11+W11+Y11+AA11+AC11+AE11+AG11+AI11+AK11+AO11+AQ11+AS11+AU11+AW11+AY11+BA11+BC11+BE11+BG11+BI11+BK11+BM11 -> 0 | C11: =+F11+H11+J11+L11+N11+P11+R11+T11+V11+X11+Z11+AB11+AD11+AF11+AH11+AJ11+AL11+AP11+AR11+AT11+AV11+AX11+AZ11+BB11+BD11+BF11+BH11+BJ11+BL11+BN11 -> 0 | D11: =+C11/B11 -> #DIV/0!
A12: CESAR POLANCO | B12: =+E12+G12+I12+K12+M12+O12+Q12+S12+U12+W12+Y12+AA12+AC12+AE12+AG12+AI12+AK12+AO12+AQ12+AS12+AU12+AW12+AY12+BA12+BC12+BE12+BG12+BI12+BK12+BM12 -> 0 | C12: =+F12+H12+J12+L12+N12+P12+R12+T12+V12+X12+Z12+AB12+AD12+AF12+AH12+AJ12+AL12+AP12+AR12+AT12+AV12+AX12+AZ12+BB12+BD12+BF12+BH12+BJ12+BL12+BN12 -> 0 | D12: =+C12/B12 -> #DIV/0!
A13: ELVIN GARCIA ROSTRAON | B13: =+E13+G13+I13+K13+M13+O13+Q13+S13+U13+W13+Y13+AA13+AC13+AE13+AG13+AI13+AK13+AO13+AQ13+AS13+AU13+AW13+AY13+BA13+BC13+BE13+BG13+BI13+BK13+BM13 -> 0 | C13: =+F13+H13+J13+L13+N13+P13+R13+T13+V13+X13+Z13+AB13+AD13+AF13+AH13+AJ13+AL13+AP13+AR13+AT13+AV13+AX13+AZ13+BB13+BD13+BF13+BH13+BJ13+BL13+BN13 -> 0 | D13: =+C13/B13 -> #DIV/0!
A14: ELVIS FLORES | B14: =+E14+G14+I14+K14+M14+O14+Q14+S14+U14+W14+Y14+AA14+AC14+AE14+AG14+AI14+AK14+AO14+AQ14+AS14+AU14+AW14+AY14+BA14+BC14+BE14+BG14+BI14+BK14+BM14 -> 0 | C14: =+F14+H14+J14+L14+N14+P14+R14+T14+V14+X14+Z14+AB14+AD14+AF14+AH14+AJ14+AL14+AP14+AR14+AT14+AV14+AX14+AZ14+BB14+BD14+BF14+BH14+BJ14+BL14+BN14 -> 0 | D14: =+C14/B14 -> #DIV/0!
A15: GABRIEL VEGA | B15: =+E15+G15+I15+K15+M15+O15+Q15+S15+U15+W15+Y15+AA15+AC15+AE15+AG15+AI15+AK15+AO15+AQ15+AS15+AU15+AW15+AY15+BA15+BC15+BE15+BG15+BI15+BK15+BM15 -> 0 | C15: =+F15+H15+J15+L15+N15+P15+R15+T15+V15+X15+Z15+AB15+AD15+AF15+AH15+AJ15+AL15+AP15+AR15+AT15+AV15+AX15+AZ15+BB15+BD15+BF15+BH15+BJ15+BL15+BN15 -> 0 | D15: =+C15/B15 -> #DIV/0!
A16: HOLLMAN ZAPATA | B16: =+E16+G16+I16+K16+M16+O16+Q16+S16+U16+W16+Y16+AA16+AC16+AE16+AG16+AI16+AK16+AO16+AQ16+AS16+AU16+AW16+AY16+BA16+BC16+BE16+BG16+BI16+BK16+BM16 -> 0 | C16: =+F16+H16+J16+L16+N16+P16+R16+T16+V16+X16+Z16+AB16+AD16+AF16+AH16+AJ16+AL16+AP16+AR16+AT16+AV16+AX16+AZ16+BB16+BD16+BF16+BH16+BJ16+BL16+BN16 -> 0 | D16: =+C16/B16 -> #DIV/0!
A17: JOSE ANTONIO VAZQUEZ | B17: =+E17+G17+I17+K17+M17+O17+Q17+S17+U17+W17+Y17+AA17+AC17+AE17+AG17+AI17+AK17+AO17+AQ17+AS17+AU17+AW17+AY17+BA17+BC17+BE17+BG17+BI17+BK17+BM17 -> 0 | C17: =+F17+H17+J17+L17+N17+P17+R17+T17+V17+X17+Z17+AB17+AD17+AF17+AH17+AJ17+AL17+AP17+AR17+AT17+AV17+AX17+AZ17+BB17+BD17+BF17+BH17+BJ17+BL17+BN17 -> 0 | D17: =+C17/B17 -> #DIV/0!
A18: JOSE DAMIEL LOZA | B18: =+E18+G18+I18+K18+M18+O18+Q18+S18+U18+W18+Y18+AA18+AC18+AE18+AG18+AI18+AK18+AO18+AQ18+AS18+AU18+AW18+AY18+BA18+BC18+BE18+BG18+BI18+BK18+BM18 -> 0 | C18: =+F18+H18+J18+L18+N18+P18+R18+T18+V18+X18+Z18+AB18+AD18+AF18+AH18+AJ18+AL18+AP18+AR18+AT18+AV18+AX18+AZ18+BB18+BD18+BF18+BH18+BJ18+BL18+BN18 -> 0 | D18: =+C18/B18 -> #DIV/0!
A19: JOSE DENIS PASTRAN | B19: =+E19+G19+I19+K19+M19+O19+Q19+S19+U19+W19+Y19+AA19+AC19+AE19+AG19+AI19+AK19+AO19+AQ19+AS19+AU19+AW19+AY19+BA19+BC19+BE19+BG19+BI19+BK19+BM19 -> 0 | C19: =+F19+H19+J19+L19+N19+P19+R19+T19+V19+X19+Z19+AB19+AD19+AF19+AH19+AJ19+AL19+AP19+AR19+AT19+AV19+AX19+AZ19+BB19+BD19+BF19+BH19+BJ19+BL19+BN19 -> 0 | D19: =+C19/B19 -> #DIV/0!
... A31: SERGIO GUZMAN | B31: =+E31+G31+I31+K31+M31+O31+Q31+S31+U31+W31+Y31+AA31+AC31+AE31+AG31+AI31+AK31+AO31+AQ31+AS31+AU31+AW31+AY31+BA31+BC31+BE31+BG31+BI31+BK31+BM31 -> 0 | C31: =+F31+H31+J31+L31+N31+P31+R31+T31+V31+X31+Z31+AB31+AD31+AF31+AH31+AJ31+AL31+AP31+AR31+AT31+AV31+AX31+AZ31+BB31+BD31+BF31+BH31+BJ31+BL31+BN31 -> 0 | D31: =+C31/B31 -> #DIV/0!
A32: YERIL MANUEL ZAPATA
A33: Jason | G33: 0.25 | H33: 50 | J33: 60
B34: =+E34+G34+I34+K34+M34+O34+Q34+S34+U34+W34+Y34+AA34+AC34+AE34+AG34+AI34+AK34+AO34+AQ34+AS34+AU34+AW34+AY34+BA34+BC34+BE34+BG34+BI34+BK34+BM34 -> 0 | C34: =+F34+H34+J34+L34+N34+P34+R34+T34+V34+X34+Z34+AB34+AD34+AF34+AH34+AJ34+AL34+AP34+AR34+AT34+AV34+AX34+AZ34+BB34+BD34+BF34+BH34+BJ34+BL34+BN34 -> 0 | D34: =+C34/B34 -> #DIV/0!
B35: =+E35+G35+I35+K35+M35+O35+Q35+S35+U35+W35+Y35+AA35+AC35+AE35+AG35+AI35+AK35+AO35+AQ35+AS35+AU35+AW35+AY35+BA35+BC35+BE35+BG35+BI35+BK35+BM35 -> 0 | C35: =+F35+H35+J35+L35+N35+P35+R35+T35+V35+X35+Z35+AB35+AD35+AF35+AH35+AJ35+AL35+AP35+AR35+AT35+AV35+AX35+AZ35+BB35+BD35+BF35+BH35+BJ35+BL35+BN35 -> 0 | D35: =+C35/B35 -> #DIV/0!
B36: =+E36+G36+I36+K36+M36+O36+Q36+S36+U36+W36+Y36+AA36+AC36+AE36+AG36+AI36+AK36+AO36+AQ36+AS36+AU36+AW36+AY36+BA36+BC36+BE36+BG36+BI36+BK36+BM36 -> 0 | C36: =+F36+H36+J36+L36+N36+P36+R36+T36+V36+X36+Z36+AB36+AD36+AF36+AH36+AJ36+AL36+AP36+AR36+AT36+AV36+AX36+AZ36+BB36+BD36+BF36+BH36+BJ36+BL36+BN36 -> 0 | D36: =+C36/B36 -> #DIV/0!
B37: =+E37+G37+I37+K37+M37+O37+Q37+S37+U37+W37+Y37+AA37+AC37+AE37+AG37+AI37+AK37+AO37+AQ37+AS37+AU37+AW37+AY37+BA37+BC37+BE37+BG37+BI37+BK37+BM37 -> 0 | C37: =+F37+H37+J37+L37+N37+P37+R37+T37+V37+X37+Z37+AB37+AD37+AF37+AH37+AJ37+AL37+AP37+AR37+AT37+AV37+AX37+AZ37+BB37+BD37+BF37+BH37+BJ37+BL37+BN37 -> 0 | D37: =+C37/B37 -> #DIV/0!
B38: =+E38+G38+I38+K38+M38+O38+Q38+S38+U38+W38+Y38+AA38+AC38+AE38+AG38+AI38+AK38+AO38+AQ38+AS38+AU38+AW38+AY38+BA38+BC38+BE38+BG38+BI38+BK38+BM38 -> 0 | C38: =+F38+H38+J38+L38+N38+P38+R38+T38+V38+X38+Z38+AB38+AD38+AF38+AH38+AJ38+AL38+AP38+AR38+AT38+AV38+AX38+AZ38+BB38+BD38+BF38+BH38+BJ38+BL38+BN38 -> 0 | D38: =+C38/B38 -> #DIV/0!
B39: =+E39+G39+I39+K39+M39+O39+Q39+S39+U39+W39+Y39+AA39+AC39+AE39+AG39+AI39+AK39+AO39+AQ39+AS39+AU39+AW39+AY39+BA39+BC39+BE39+BG39+BI39+BK39+BM39 -> 0 | C39: =+F39+H39+J39+L39+N39+P39+R39+T39+V39+X39+Z39+AB39+AD39+AF39+AH39+AJ39+AL39+AP39+AR39+AT39+AV39+AX39+AZ39+BB39+BD39+BF39+BH39+BJ39+BL39+BN39 -> 0 | D39: =+C39/B39 -> #DIV/0!
B40: =+E40+G40+I40+K40+M40+O40+Q40+S40+U40+W40+Y40+AA40+AC40+AE40+AG40+AI40+AK40+AO40+AQ40+AS40+AU40+AW40+AY40+BA40+BC40+BE40+BG40+BI40+BK40+BM40 -> 0 | C40: =+F40+H40+J40+L40+N40+P40+R40+T40+V40+X40+Z40+AB40+AD40+AF40+AH40+AJ40+AL40+AP40+AR40+AT40+AV40+AX40+AZ40+BB40+BD40+BF40+BH40+BJ40+BL40+BN40 -> 0 | D40: =+C40/B40 -> #DIV/0!
B41: =+E41+G41+I41+K41+M41+O41+Q41+S41+U41+W41+Y41+AA41+AC41+AE41+AG41+AI41+AK41+AO41+AQ41+AS41+AU41+AW41+AY41+BA41+BC41+BE41+BG41+BI41+BK41+BM41 -> 0 | C41: =+F41+H41+J41+L41+N41+P41+R41+T41+V41+X41+Z41+AB41+AD41+AF41+AH41+AJ41+AL41+AP41+AR41+AT41+AV41+AX41+AZ41+BB41+BD41+BF41+BH41+BJ41+BL41+BN41 -> 0 | D41: =+C41/B41 -> #DIV/0!
B42: =+E42+G42+I42+K42+M42+O42+Q42+S42+U42+W42+Y42+AA42+AC42+AE42+AG42+AI42+AK42+AO42+AQ42+AS42+AU42+AW42+AY42+BA42+BC42+BE42+BG42+BI42+BK42+BM42 -> 0 | C42: =+F42+H42+J42+L42+N42+P42+R42+T42+V42+X42+Z42+AB42+AD42+AF42+AH42+AJ42+AL42+AP42+AR42+AT42+AV42+AX42+AZ42+BB42+BD42+BF42+BH42+BJ42+BL42+BN42 -> 0 | D42: =+C42/B42 -> #DIV/0!
B43: =+E43+G43+I43+K43+M43+O43+Q43+S43+U43+W43+Y43+AA43+AC43+AE43+AG43+AI43+AK43+AO43+AQ43+AS43+AU43+AW43+AY43+BA43+BC43+BE43+BG43+BI43+BK43+BM43 -> 0 | C43: =+F43+H43+J43+L43+N43+P43+R43+T43+V43+X43+Z43+AB43+AD43+AF43+AH43+AJ43+AL43+AP43+AR43+AT43+AV43+AX43+AZ43+BB43+BD43+BF43+BH43+BJ43+BL43+BN43 -> 0 | D43: =+C43/B43 -> #DIV/0!
B44: =+E44+G44+I44+K44+M44+O44+Q44+S44+U44+W44+Y44+AA44+AC44+AE44+AG44+AI44+AK44+AO44+AQ44+AS44+AU44+AW44+AY44+BA44+BC44+BE44+BG44+BI44+BK44+BM44 -> 0 | C44: =+F44+H44+J44+L44+N44+P44+R44+T44+V44+X44+Z44+AB44+AD44+AF44+AH44+AJ44+AL44+AP44+AR44+AT44+AV44+AX44+AZ44+BB44+BD44+BF44+BH44+BJ44+BL44+BN44 -> 0 | D44: =+C44/B44 -> #DIV/0!
B45: =+E45+G45+I45+K45+M45+O45+Q45+S45+U45+W45+Y45+AA45+AC45+AE45+AG45+AI45+AK45+AO45+AQ45+AS45+AU45+AW45+AY45+BA45+BC45+BE45+BG45+BI45+BK45+BM45 -> 0 | C45: =+F45+H45+J45+L45+N45+P45+R45+T45+V45+X45+Z45+AB45+AD45+AF45+AH45+AJ45+AL45+AP45+AR45+AT45+AV45+AX45+AZ45+BB45+BD45+BF45+BH45+BJ45+BL45+BN45 -> 0 | D45: =+C45/B45 -> #DIV/0!
... B51: =+E51+G51+I51+K51+M51+O51+Q51+S51+U51+W51+Y51+AA51+AC51+AE51+AG51+AI51+AK51+AO51+AQ51+AS51+AU51+AW51+AY51+BA51+BC51+BE51+BG51+BI51+BK51+BM51 -> 0 | C51: =+F51+H51+J51+L51+N51+P51+R51+T51+V51+X51+Z51+AB51+AD51+AF51+AH51+AJ51+AL51+AP51+AR51+AT51+AV51+AX51+AZ51+BB51+BD51+BF51+BH51+BJ51+BL51+BN51 -> 0 | D51: =+C51/B51 -> #DIV/0!

Sheet amarre 3
A1: Control de actividades diarias
A2: Labor | B2: AMARRE 3
A3: Finca: | B3: =+'amarre 1'!B3 -> Las Mesas
A4: Mes | B4: =+'amarre 1'!B4
E5: Días del mes
A6: Trabajador | B6: hrs | C6: # tramos | D6: # tramos/h | E6: 1 | G6: 2 | I6: 3 | K6: 4 | M6: 5 | O6: 6 | Q6: 7 | S6: 8 | U6: 9 | W6: 10 | Y6: 11 | AA6: 12 | AC6: 13 | AE6: 14 | AG6: 15 | AI6: 16 | AK6: 17 | AM6: 18 | AO6: 19 | AQ6: 20 | AS6: 21 | AU6: 22 | AW6: 23 | AY6: 24 | BA6: 25 | BC6: 26 | BE6: 27 | BG6: 28 | BI6: 29 | BK6: 30 | BM6: 31
E7: Hrs | F7: # tramos | G7: Hrs | H7: # tramos | I7: Hrs | J7: # tramos | K7: Hrs | L7: # tramos | M7: Hrs | N7: # tramos | O7: Hrs | P7: # tramos | Q7: Hrs | R7: # tramos | S7: Hrs | T7: # tramos | U7: Hrs | V7: # tramos | W7: Hrs | X7: # tramos | Y7: Hrs | Z7: # tramos | AA7: Hrs | AB7: # tramos | AC7: Hrs | AD7: # tramos | AE7: Hrs | AF7: # tramos | AG7: Hrs | AH7: # tramos | AI7: Hrs | AJ7: # tramos | AK7: Hrs | AL7: # tramos | AM7: Hrs | AN7: # tramos | AO7: Hrs | AP7: # tramos | AQ7: Hrs | AR7: # tramos | AS7: Hrs | AT7: # tramos | AU7: Hrs | AV7: # tramos | AW7: Hrs | AX7: # tramos | AY7: Hrs | AZ7: # tramos | BA7: Hrs | BB7: # tramos | BC7: Hrs | BD7: # tramos | BE7: Hrs | BF7: # tramos | BG7: Hrs | BH7: # tramos | BI7: Hrs | BJ7: # tramos | BK7: Hrs | BL7: # tramos | BM7: Hrs | BN7: # tramos
A8: ALONZO LOZA | B8: =+E8+G8+I8+K8+M8+O8+Q8+S8+U8+W8+Y8+AA8+AC8+AE8+AG8+AI8+AK8+AO8+AQ8+AS8+AU8+AW8+AY8+BA8+BC8+BE8+BG8+BI8+BK8+BM8 -> 0 | C8: =+F8+H8+J8+L8+N8+P8+R8+T8+V8+X8+Z8+AB8+AD8+AF8+AH8+AJ8+AL8+AP8+AR8+AT8+AV8+AX8+AZ8+BB8+BD8+BF8+BH8+BJ8+BL8+BN8 -> 0 | D8: =+C8/B8 -> #DIV/0!
A9: ALVIN ALCANTARA | B9: =+E9+G9+I9+K9+M9+O9+Q9+S9+U9+W9+Y9+AA9+AC9+AE9+AG9+AI9+AK9+AO9+AQ9+AS9+AU9+AW9+AY9+BA9+BC9+BE9+BG9+BI9+BK9+BM9 -> 0 | C9: =+F9+H9+J9+L9+N9+P9+R9+T9+V9+X9+Z9+AB9+AD9+AF9+AH9+AJ9+AL9+AP9+AR9+AT9+AV9+AX9+AZ9+BB9+BD9+BF9+BH9+BJ9+BL9+BN9 -> 0 | D9: =+C9/B9 -> #DIV/0!
A10: BILOMAR URBINA | B10: =+E10+G10+I10+K10+M10+O10+Q10+S10+U10+W10+Y10+AA10+AC10+AE10+AG10+AI10+AK10+AO10+AQ10+AS10+AU10+AW10+AY10+BA10+BC10+BE10+BG10+BI10+BK10+BM10 -> 0 | C10: =+F10+H10+J10+L10+N10+P10+R10+T10+V10+X10+Z10+AB10+AD10+AF10+AH10+AJ10+AL10+AP10+AR10+AT10+AV10+AX10+AZ10+BB10+BD10+BF10+BH10+BJ10+BL10+BN10 -> 0 | D10: =+C10/B10 -> #DIV/0!
A11: CARLOS ANTHONIO JIMENEZ | B11: =+E11+G11+I11+K11+M11+O11+Q11+S11+U11+W11+Y11+AA11+AC11+AE11+AG11+AI11+AK11+AO11+AQ11+AS11+AU11+AW11+AY11+BA11+BC11+BE11+BG11+BI11+BK11+BM11 -> 0 | C11: =+F11+H11+J11+L11+N11+P11+R11+T11+V11+X11+Z11+AB11+AD11+AF11+AH11+AJ11+AL11+AP11+AR11+AT11+AV11+AX11+AZ11+BB11+BD11+BF11+BH11+BJ11+BL11+BN11 -> 0 | D11: =+C11/B11 -> #DIV/0!
A12: CESAR POLANCO | B12: =+E12+G12+I12+K12+M12+O12+Q12+S12+U12+W12+Y12+AA12+AC12+AE12+AG12+AI12+AK12+AO12+AQ12+AS12+AU12+AW12+AY12+BA12+BC12+BE12+BG12+BI12+BK12+BM12 -> 0 | C12: =+F12+H12+J12+L12+N12+P12+R12+T12+V12+X12+Z12+AB12+AD12+AF12+AH12+AJ12+AL12+AP12+AR12+AT12+AV12+AX12+AZ12+BB12+BD12+BF12+BH12+BJ12+BL12+BN12 -> 0 | D12: =+C12/B12 -> #DIV/0!
A13: ELVIN GARCIA ROSTRAON | B13: =+E13+G13+I13+K13+M13+O13+Q13+S13+U13+W13+Y13+AA13+AC13+AE13+AG13+AI13+AK13+AO13+AQ13+AS13+AU13+AW13+AY13+BA13+BC13+BE13+BG13+BI13+BK13+BM13 -> 0 | C13: =+F13+H13+J13+L13+N13+P13+R13+T13+V13+X13+Z13+AB13+AD13+AF13+AH13+AJ13+AL13+AP13+AR13+AT13+AV13+AX13+AZ13+BB13+BD13+BF13+BH13+BJ13+BL13+BN13 -> 0 | D13: =+C13/B13 -> #DIV/0!
A14: ELVIS FLORES | B14: =+E14+G14+I14+K14+M14+O14+Q14+S14+U14+W14+Y14+AA14+AC14+AE14+AG14+AI14+AK14+AO14+AQ14+AS14+AU14+AW14+AY14+BA14+BC14+BE14+BG14+BI14+BK14+BM14 -> 0 | C14: =+F14+H14+J14+L14+N14+P14+R14+T14+V14+X14+Z14+AB14+AD14+AF14+AH14+AJ14+AL14+AP14+AR14+AT14+AV14+AX14+AZ14+BB14+BD14+BF14+BH14+BJ14+BL14+BN14 -> 0 | D14: =+C14/B14 -> #DIV/0!
A15: GABRIEL VEGA | B15: =+E15+G15+I15+K15+M15+O15+Q15+S15+U15+W15+Y15+AA15+AC15+AE15+AG15+AI15+AK15+AO15+AQ15+AS15+AU15+AW15+AY15+BA15+BC15+BE15+BG15+BI15+BK15+BM15 -> 0 | C15: =+F15+H15+J15+L15+N15+P15+R15+T15+V15+X15+Z15+AB15+AD15+AF15+AH15+AJ15+AL15+AP15+AR15+AT15+AV15+AX15+AZ15+BB15+BD15+BF15+BH15+BJ15+BL15+BN15 -> 0 | D15: =+C15/B15 -> #DIV/0!
A16: HOLLMAN ZAPATA | B16: =+E16+G16+I16+K16+M16+O16+Q16+S16+U16+W16+Y16+AA16+AC16+AE16+AG16+AI16+AK16+AO16+AQ16+AS16+AU16+AW16+AY16+BA16+BC16+BE16+BG16+BI16+BK16+BM16 -> 0 | C16: =+F16+H16+J16+L16+N16+P16+R16+T16+V16+X16+Z16+AB16+AD16+AF16+AH16+AJ16+AL16+AP16+AR16+AT16+AV16+AX16+AZ16+BB16+BD16+BF16+BH16+BJ16+BL16+BN16 -> 0 | D16: =+C16/B16 -> #DIV/0!
A17: JOSE ANTONIO VAZQUEZ | B17: =+E17+G17+I17+K17+M17+O17+Q17+S17+U17+W17+Y17+AA17+AC17+AE17+AG17+AI17+AK17+AO17+AQ17+AS17+AU17+AW17+AY17+BA17+BC17+BE17+BG17+BI17+BK17+BM17 -> 0 | C17: =+F17+H17+J17+L17+N17+P17+R17+T17+V17+X17+Z17+AB17+AD17+AF17+AH17+AJ17+AL17+AP17+AR17+AT17+AV17+AX17+AZ17+BB17+BD17+BF17+BH17+BJ17+BL17+BN17 -> 0 | D17: =+C17/B17 -> #DIV/0!
A18: JOSE DAMIEL LOZA | B18: =+E18+G18+I18+K18+M18+O18+Q18+S18+U18+W18+Y18+AA18+AC18+AE18+AG18+AI18+AK18+AO18+AQ18+AS18+AU18+AW18+AY18+BA18+BC18+BE18+BG18+BI18+BK18+BM18 -> 0 | C18: =+F18+H18+J18+L18+N18+P18+R18+T18+V18+X18+Z18+AB18+AD18+AF18+AH18+AJ18+AL18+AP18+AR18+AT18+AV18+AX18+AZ18+BB18+BD18+BF18+BH18+BJ18+BL18+BN18 -> 0 | D18: =+C18/B18 -> #DIV/0!
A19: JOSE DENIS PASTRAN | B19: =+E19+G19+I19+K19+M19+O19+Q19+S19+U19+W19+Y19+AA19+AC19+AE19+AG19+AI19+AK19+AO19+AQ19+AS19+AU19+AW19+AY19+BA19+BC19+BE19+BG19+BI19+BK19+BM19 -> 0 | C19: =+F19+H19+J19+L19+N19+P19+R19+T19+V19+X19+Z19+AB19+AD19+AF19+AH19+AJ19+AL19+AP19+AR19+AT19+AV19+AX19+AZ19+BB19+BD19+BF19+BH19+BJ19+BL19+BN19 -> 0 | D19: =+C19/B19 -> #DIV/0!
... A31: SERGIO GUZMAN | B31: =+E31+G31+I31+K31+M31+O31+Q31+S31+U31+W31+Y31+AA31+AC31+AE31+AG31+AI31+AK31+AO31+AQ31+AS31+AU31+AW31+AY31+BA31+BC31+BE31+BG31+BI31+BK31+BM31 -> 0 | C31: =+F31+H31+J31+L31+N31+P31+R31+T31+V31+X31+Z31+AB31+AD31+AF31+AH31+AJ31+AL31+AP31+AR31+AT31+AV31+AX31+AZ31+BB31+BD31+BF31+BH31+BJ31+BL31+BN31 -> 0 | D31: =+C31/B31 -> #DIV/0!
A32: YERIL MANUEL ZAPATA
B33: =+E33+G33+I33+K33+M33+O33+Q33+S33+U33+W33+Y33+AA33+AC33+AE33+AG33+AI33+AK33+AO33+AQ33+AS33+AU33+AW33+AY33+BA33+BC33+BE33+BG33+BI33+BK33+BM33 -> 0 | C33: =+F33+H33+J33+L33+N33+P33+R33+T33+V33+X33+Z33+AB33+AD33+AF33+AH33+AJ33+AL33+AP33+AR33+AT33+AV33+AX33+AZ33+BB33+BD33+BF33+BH33+BJ33+BL33+BN33 -> 0 | D33: =+C33/B33 -> #DIV/0!
B34: =+E34+G34+I34+K34+M34+O34+Q34+S34+U34+W34+Y34+AA34+AC34+AE34+AG34+AI34+AK34+AO34+AQ34+AS34+AU34+AW34+AY34+BA34+BC34+BE34+BG34+BI34+BK34+BM34 -> 0 | C34: =+F34+H34+J34+L34+N34+P34+R34+T34+V34+X34+Z34+AB34+AD34+AF34+AH34+AJ34+AL34+AP34+AR34+AT34+AV34+AX34+AZ34+BB34+BD34+BF34+BH34+BJ34+BL34+BN34 -> 0 | D34: =+C34/B34 -> #DIV/0!
B35: =+E35+G35+I35+K35+M35+O35+Q35+S35+U35+W35+Y35+AA35+AC35+AE35+AG35+AI35+AK35+AO35+AQ35+AS35+AU35+AW35+AY35+BA35+BC35+BE35+BG35+BI35+BK35+BM35 -> 0 | C35: =+F35+H35+J35+L35+N35+P35+R35+T35+V35+X35+Z35+AB35+AD35+AF35+AH35+AJ35+AL35+AP35+AR35+AT35+AV35+AX35+AZ35+BB35+BD35+BF35+BH35+BJ35+BL35+BN35 -> 0 | D35: =+C35/B35 -> #DIV/0!
B36: =+E36+G36+I36+K36+M36+O36+Q36+S36+U36+W36+Y36+AA36+AC36+AE36+AG36+AI36+AK36+AO36+AQ36+AS36+AU36+AW36+AY36+BA36+BC36+BE36+BG36+BI36+BK36+BM36 -> 0 | C36: =+F36+H36+J36+L36+N36+P36+R36+T36+V36+X36+Z36+AB36+AD36+AF36+AH36+AJ36+AL36+AP36+AR36+AT36+AV36+AX36+AZ36+BB36+BD36+BF36+BH36+BJ36+BL36+BN36 -> 0 | D36: =+C36/B36 -> #DIV/0!
B37: =+E37+G37+I37+K37+M37+O37+Q37+S37+U37+W37+Y37+AA37+AC37+AE37+AG37+AI37+AK37+AO37+AQ37+AS37+AU37+AW37+AY37+BA37+BC37+BE37+BG37+BI37+BK37+BM37 -> 0 | C37: =+F37+H37+J37+L37+N37+P37+R37+T37+V37+X37+Z37+AB37+AD37+AF37+AH37+AJ37+AL37+AP37+AR37+AT37+AV37+AX37+AZ37+BB37+BD37+BF37+BH37+BJ37+BL37+BN37 -> 0 | D37: =+C37/B37 -> #DIV/0!
B38: =+E38+G38+I38+K38+M38+O38+Q38+S38+U38+W38+Y38+AA38+AC38+AE38+AG38+AI38+AK38+AO38+AQ38+AS38+AU38+AW38+AY38+BA38+BC38+BE38+BG38+BI38+BK38+BM38 -> 0 | C38: =+F38+H38+J38+L38+N38+P38+R38+T38+V38+X38+Z38+AB38+AD38+AF38+AH38+AJ38+AL38+AP38+AR38+AT38+AV38+AX38+AZ38+BB38+BD38+BF38+BH38+BJ38+BL38+BN38 -> 0 | D38: =+C38/B38 -> #DIV/0!
B39: =+E39+G39+I39+K39+M39+O39+Q39+S39+U39+W39+Y39+AA39+AC39+AE39+AG39+AI39+AK39+AO39+AQ39+AS39+AU39+AW39+AY39+BA39+BC39+BE39+BG39+BI39+BK39+BM39 -> 0 | C39: =+F39+H39+J39+L39+N39+P39+R39+T39+V39+X39+Z39+AB39+AD39+AF39+AH39+AJ39+AL39+AP39+AR39+AT39+AV39+AX39+AZ39+BB39+BD39+BF39+BH39+BJ39+BL39+BN39 -> 0 | D39: =+C39/B39 -> #DIV/0!
B40: =+E40+G40+I40+K40+M40+O40+Q40+S40+U40+W40+Y40+AA40+AC40+AE40+AG40+AI40+AK40+AO40+AQ40+AS40+AU40+AW40+AY40+BA40+BC40+BE40+BG40+BI40+BK40+BM40 -> 0 | C40: =+F40+H40+J40+L40+N40+P40+R40+T40+V40+X40+Z40+AB40+AD40+AF40+AH40+AJ40+AL40+AP40+AR40+AT40+AV40+AX40+AZ40+BB40+BD40+BF40+BH40+BJ40+BL40+BN40 -> 0 | D40: =+C40/B40 -> #DIV/0!
B41: =+E41+G41+I41+K41+M41+O41+Q41+S41+U41+W41+Y41+AA41+AC41+AE41+AG41+AI41+AK41+AO41+AQ41+AS41+AU41+AW41+AY41+BA41+BC41+BE41+BG41+BI41+BK41+BM41 -> 0 | C41: =+F41+H41+J41+L41+N41+P41+R41+T41+V41+X41+Z41+AB41+AD41+AF41+AH41+AJ41+AL41+AP41+AR41+AT41+AV41+AX41+AZ41+BB41+BD41+BF41+BH41+BJ41+BL41+BN41 -> 0 | D41: =+C41/B41 -> #DIV/0!
B42: =+E42+G42+I42+K42+M42+O42+Q42+S42+U42+W42+Y42+AA42+AC42+AE42+AG42+AI42+AK42+AO42+AQ42+AS42+AU42+AW42+AY42+BA42+BC42+BE42+BG42+BI42+BK42+BM42 -> 0 | C42: =+F42+H42+J42+L42+N42+P42+R42+T42+V42+X42+Z42+AB42+AD42+AF42+AH42+AJ42+AL42+AP42+AR42+AT42+AV42+AX42+AZ42+BB42+BD42+BF42+BH42+BJ42+BL42+BN42 -> 0 | D42: =+C42/B42 -> #DIV/0!
B43: =+E43+G43+I43+K43+M43+O43+Q43+S43+U43+W43+Y43+AA43+AC43+AE43+AG43+AI43+AK43+AO43+AQ43+AS43+AU43+AW43+AY43+BA43+BC43+BE43+BG43+BI43+BK43+BM43 -> 0 | C43: =+F43+H43+J43+L43+N43+P43+R43+T43+V43+X43+Z43+AB43+AD43+AF43+AH43+AJ43+AL43+AP43+AR43+AT43+AV43+AX43+AZ43+BB43+BD43+BF43+BH43+BJ43+BL43+BN43 -> 0 | D43: =+C43/B43 -> #DIV/0!
B44: =+E44+G44+I44+K44+M44+O44+Q44+S44+U44+W44+Y44+AA44+AC44+AE44+AG44+AI44+AK44+AO44+AQ44+AS44+AU44+AW44+AY44+BA44+BC44+BE44+BG44+BI44+BK44+BM44 -> 0 | C44: =+F44+H44+J44+L44+N44+P44+R44+T44+V44+X44+Z44+AB44+AD44+AF44+AH44+AJ44+AL44+AP44+AR44+AT44+AV44+AX44+AZ44+BB44+BD44+BF44+BH44+BJ44+BL44+BN44 -> 0 | D44: =+C44/B44 -> #DIV/0!
... B50: =+E50+G50+I50+K50+M50+O50+Q50+S50+U50+W50+Y50+AA50+AC50+AE50+AG50+AI50+AK50+AO50+AQ50+AS50+AU50+AW50+AY50+BA50+BC50+BE50+BG50+BI50+BK50+BM50 -> 0 | C50: =+F50+H50+J50+L50+N50+P50+R50+T50+V50+X50+Z50+AB50+AD50+AF50+AH50+AJ50+AL50+AP50+AR50+AT50+AV50+AX50+AZ50+BB50+BD50+BF50+BH50+BJ50+BL50+BN50 -> 0 | D50: =+C50/B50 -> #DIV/0!

Sheet amarre 4
A1: Control de actividades diarias
A2: Labor | B2: AMARRE 4
A3: Finca: | B3: =+'amarre 1'!B3 -> Las Mesas
A4: Mes | B4: =+'amarre 1'!B4
E5: Días del mes
A6: Trabajador | B6: hrs | C6: # tramos | D6: # tramos/h | E6: 1 | G6: 2 | I6: 3 | K6: 4 | M6: 5 | O6: 6 | Q6: 7 | S6: 8 | U6: 9 | W6: 10 | Y6: 11 | AA6: 12 | AC6: 13 | AE6: 14 | AG6: 15 | AI6: 16 | AK6: 17 | AM6: 18 | AO6: 19 | AQ6: 20 | AS6: 21 | AU6: 22 | AW6: 23 | AY6: 24 | BA6: 25 | BC6: 26 | BE6: 27 | BG6: 28 | BI6: 29 | BK6: 30 | BM6: 31
E7: Hrs | F7: # tramos | G7: Hrs | H7: # tramos | I7: Hrs | J7: # tramos | K7: Hrs | L7: # tramos | M7: Hrs | N7: # tramos | O7: Hrs | P7: # tramos | Q7: Hrs | R7: # tramos | S7: Hrs | T7: # tramos | U7: Hrs | V7: # tramos | W7: Hrs | X7: # tramos | Y7: Hrs | Z7: # tramos | AA7: Hrs | AB7: # tramos | AC7: Hrs | AD7: # tramos | AE7: Hrs | AF7: # tramos | AG7: Hrs | AH7: # tramos | AI7: Hrs | AJ7: # tramos | AK7: Hrs | AL7: # tramos | AM7: Hrs | AN7: # tramos | AO7: Hrs | AP7: # tramos | AQ7: Hrs | AR7: # tramos | AS7: Hrs | AT7: # tramos | AU7: Hrs | AV7: # tramos | AW7: Hrs | AX7: # tramos | AY7: Hrs | AZ7: # tramos | BA7: Hrs | BB7: # tramos | BC7: Hrs | BD7: # tramos | BE7: Hrs | BF7: # tramos | BG7: Hrs | BH7: # tramos | BI7: Hrs | BJ7: # tramos | BK7: Hrs | BL7: # tramos | BM7: Hrs | BN7: # tramos
A8: =+cosecha!A8 -> WILMER ALTAMIRANO | B8: =+E8+G8+I8+K8+M8+O8+Q8+S8+U8+W8+Y8+AA8+AC8+AE8+AG8+AI8+AK8+AO8+AQ8+AS8+AU8+AW8+AY8+BA8+BC8+BE8+BG8+BI8+BK8+BM8 -> 0 | C8: =+F8+H8+J8+L8+N8+P8+R8+T8+V8+X8+Z8+AB8+AD8+AF8+AH8+AJ8+AL8+AP8+AR8+AT8+AV8+AX8+AZ8+BB8+BD8+BF8+BH8+BJ8+BL8+BN8 -> 0 | D8: =+C8/B8 -> #DIV/0!
A9: =+cosecha!A9 -> Jefry jardín | B9: =+E9+G9+I9+K9+M9+O9+Q9+S9+U9+W9+Y9+AA9+AC9+AE9+AG9+AI9+AK9+AO9+AQ9+AS9+AU9+AW9+AY9+BA9+BC9+BE9+BG9+BI9+BK9+BM9 -> 0 | C9: =+F9+H9+J9+L9+N9+P9+R9+T9+V9+X9+Z9+AB9+AD9+AF9+AH9+AJ9+AL9+AP9+AR9+AT9+AV9+AX9+AZ9+BB9+BD9+BF9+BH9+BJ9+BL9+BN9 -> 0 | D9: =+C9/B9 -> #DIV/0!
A10: =+cosecha!A10 -> JEFRAN POLANCO | B10: =+E10+G10+I10+K10+M10+O10+Q10+S10+U10+W10+Y10+AA10+AC10+AE10+AG10+AI10+AK10+AO10+AQ10+AS10+AU10+AW10+AY10+BA10+BC10+BE10+BG10+BI10+BK10+BM10 -> 0 | C10: =+F10+H10+J10+L10+N10+P10+R10+T10+V10+X10+Z10+AB10+AD10+AF10+AH10+AJ10+AL10+AP10+AR10+AT10+AV10+AX10+AZ10+BB10+BD10+BF10+BH10+BJ10+BL10+BN10 -> 0 | D10: =+C10/B10 -> #DIV/0!
A11: =+cosecha!A11 -> JUAN FIDENCIO | B11: =+E11+G11+I11+K11+M11+O11+Q11+S11+U11+W11+Y11+AA11+AC11+AE11+AG11+AI11+AK11+AO11+AQ11+AS11+AU11+AW11+AY11+BA11+BC11+BE11+BG11+BI11+BK11+BM11 -> 0 | C11: =+F11+H11+J11+L11+N11+P11+R11+T11+V11+X11+Z11+AB11+AD11+AF11+AH11+AJ11+AL11+AP11+AR11+AT11+AV11+AX11+AZ11+BB11+BD11+BF11+BH11+BJ11+BL11+BN11 -> 0 | D11: =+C11/B11 -> #DIV/0!
A12: =+cosecha!A12 -> HECTOR DÍAS | B12: =+E12+G12+I12+K12+M12+O12+Q12+S12+U12+W12+Y12+AA12+AC12+AE12+AG12+AI12+AK12+AO12+AQ12+AS12+AU12+AW12+AY12+BA12+BC12+BE12+BG12+BI12+BK12+BM12 -> 0 | C12: =+F12+H12+J12+L12+N12+P12+R12+T12+V12+X12+Z12+AB12+AD12+AF12+AH12+AJ12+AL12+AP12+AR12+AT12+AV12+AX12+AZ12+BB12+BD12+BF12+BH12+BJ12+BL12+BN12 -> 0 | D12: =+C12/B12 -> #DIV/0!
A13: =+cosecha!A13 -> MAYNOR AGUILAR | B13: =+E13+G13+I13+K13+M13+O13+Q13+S13+U13+W13+Y13+AA13+AC13+AE13+AG13+AI13+AK13+AO13+AQ13+AS13+AU13+AW13+AY13+BA13+BC13+BE13+BG13+BI13+BK13+BM13 -> 0 | C13: =+F13+H13+J13+L13+N13+P13+R13+T13+V13+X13+Z13+AB13+AD13+AF13+AH13+AJ13+AL13+AP13+AR13+AT13+AV13+AX13+AZ13+BB13+BD13+BF13+BH13+BJ13+BL13+BN13 -> 0 | D13: =+C13/B13 -> #DIV/0!
A14: =+cosecha!A14 -> HAXEL ZUAREZ | B14: =+E14+G14+I14+K14+M14+O14+Q14+S14+U14+W14+Y14+AA14+AC14+AE14+AG14+AI14+AK14+AO14+AQ14+AS14+AU14+AW14+AY14+BA14+BC14+BE14+BG14+BI14+BK14+BM14 -> 0 | C14: =+F14+H14+J14+L14+N14+P14+R14+T14+V14+X14+Z14+AB14+AD14+AF14+AH14+AJ14+AL14+AP14+AR14+AT14+AV14+AX14+AZ14+BB14+BD14+BF14+BH14+BJ14+BL14+BN14 -> 0 | D14: =+C14/B14 -> #DIV/0!
A15: =+cosecha!A15 -> MARVEN JARQUIN | B15: =+E15+G15+I15+K15+M15+O15+Q15+S15+U15+W15+Y15+AA15+AC15+AE15+AG15+AI15+AK15+AO15+AQ15+AS15+AU15+AW15+AY15+BA15+BC15+BE15+BG15+BI15+BK15+BM15 -> 0 | C15: =+F15+H15+J15+L15+N15+P15+R15+T15+V15+X15+Z15+AB15+AD15+AF15+AH15+AJ15+AL15+AP15+AR15+AT15+AV15+AX15+AZ15+BB15+BD15+BF15+BH15+BJ15+BL15+BN15 -> 0 | D15: =+C15/B15 -> #DIV/0!
A16: =+cosecha!A16 -> OSCAR AGUILAR | B16: =+E16+G16+I16+K16+M16+O16+Q16+S16+U16+W16+Y16+AA16+AC16+AE16+AG16+AI16+AK16+AO16+AQ16+AS16+AU16+AW16+AY16+BA16+BC16+BE16+BG16+BI16+BK16+BM16 -> 0 | C16: =+F16+H16+J16+L16+N16+P16+R16+T16+V16+X16+Z16+AB16+AD16+AF16+AH16+AJ16+AL16+AP16+AR16+AT16+AV16+AX16+AZ16+BB16+BD16+BF16+BH16+BJ16+BL16+BN16 -> 0 | D16: =+C16/B16 -> #DIV/0!
A17: =+cosecha!A17 -> MARLON LOPEZ | B17: =+E17+G17+I17+K17+M17+O17+Q17+S17+U17+W17+Y17+AA17+AC17+AE17+AG17+AI17+AK17+AO17+AQ17+AS17+AU17+AW17+AY17+BA17+BC17+BE17+BG17+BI17+BK17+BM17 -> 0 | C17: =+F17+H17+J17+L17+N17+P17+R17+T17+V17+X17+Z17+AB17+AD17+AF17+AH17+AJ17+AL17+AP17+AR17+AT17+AV17+AX17+AZ17+BB17+BD17+BF17+BH17+BJ17+BL17+BN17 -> 0 | D17: =+C17/B17 -> #DIV/0!
A18: =+cosecha!A18 -> DEIVIN TERCERO | B18: =+E18+G18+I18+K18+M18+O18+Q18+S18+U18+W18+Y18+AA18+AC18+AE18+AG18+AI18+AK18+AO18+AQ18+AS18+AU18+AW18+AY18+BA18+BC18+BE18+BG18+BI18+BK18+BM18 -> 0 | C18: =+F18+H18+J18+L18+N18+P18+R18+T18+V18+X18+Z18+AB18+AD18+AF18+AH18+AJ18+AL18+AP18+AR18+AT18+AV18+AX18+AZ18+BB18+BD18+BF18+BH18+BJ18+BL18+BN18 -> 0 | D18: =+C18/B18 -> #DIV/0!
A19: =+cosecha!A19 -> ELYAZAR TERCERO | B19: =+E19+G19+I19+K19+M19+O19+Q19+S19+U19+W19+Y19+AA19+AC19+AE19+AG19+AI19+AK19+AO19+AQ19+AS19+AU19+AW19+AY19+BA19+BC19+BE19+BG19+BI19+BK19+BM19 -> 0 | C19: =+F19+H19+J19+L19+N19+P19+R19+T19+V19+X19+Z19+AB19+AD19+AF19+AH19+AJ19+AL19+AP19+AR19+AT19+AV19+AX19+AZ19+BB19+BD19+BF19+BH19+BJ19+BL19+BN19 -> 0 | D19: =+C19/B19 -> #DIV/0!
... A30: =+cosecha!A30 | B30: =+E30+G30+I30+K30+M30+O30+Q30+S30+U30+W30+Y30+AA30+AC30+AE30+AG30+AI30+AK30+AO30+AQ30+AS30+AU30+AW30+AY30+BA30+BC30+BE30+BG30+BI30+BK30+BM30 -> 0 | C30: =+F30+H30+J30+L30+N30+P30+R30+T30+V30+X30+Z30+AB30+AD30+AF30+AH30+AJ30+AL30+AP30+AR30+AT30+AV30+AX30+AZ30+BB30+BD30+BF30+BH30+BJ30+BL30+BN30 -> 0 | D30: =+C30/B30 -> #DIV/0!
A31: =+cosecha!A33 | B31: =+E31+G31+I31+K31+M31+O31+Q31+S31+U31+W31+Y31+AA31+AC31+AE31+AG31+AI31+AK31+AO31+AQ31+AS31+AU31+AW31+AY31+BA31+BC31+BE31+BG31+BI31+BK31+BM31 -> 0 | C31: =+F31+H31+J31+L31+N31+P31+R31+T31+V31+X31+Z31+AB31+AD31+AF31+AH31+AJ31+AL31+AP31+AR31+AT31+AV31+AX31+AZ31+BB31+BD31+BF31+BH31+BJ31+BL31+BN31 -> 0 | D31: =+C31/B31 -> #DIV/0!
B32: =+E32+G32+I32+K32+M32+O32+Q32+S32+U32+W32+Y32+AA32+AC32+AE32+AG32+AI32+AK32+AO32+AQ32+AS32+AU32+AW32+AY32+BA32+BC32+BE32+BG32+BI32+BK32+BM32 -> 0 | C32: =+F32+H32+J32+L32+N32+P32+R32+T32+V32+X32+Z32+AB32+AD32+AF32+AH32+AJ32+AL32+AP32+AR32+AT32+AV32+AX32+AZ32+BB32+BD32+BF32+BH32+BJ32+BL32+BN32 -> 0 | D32: =+C32/B32 -> #DIV/0!
B33: =+E33+G33+I33+K33+M33+O33+Q33+S33+U33+W33+Y33+AA33+AC33+AE33+AG33+AI33+AK33+AO33+AQ33+AS33+AU33+AW33+AY33+BA33+BC33+BE33+BG33+BI33+BK33+BM33 -> 0 | C33: =+F33+H33+J33+L33+N33+P33+R33+T33+V33+X33+Z33+AB33+AD33+AF33+AH33+AJ33+AL33+AP33+AR33+AT33+AV33+AX33+AZ33+BB33+BD33+BF33+BH33+BJ33+BL33+BN33 -> 0 | D33: =+C33/B33 -> #DIV/0!
B34: =+E34+G34+I34+K34+M34+O34+Q34+S34+U34+W34+Y34+AA34+AC34+AE34+AG34+AI34+AK34+AO34+AQ34+AS34+AU34+AW34+AY34+BA34+BC34+BE34+BG34+BI34+BK34+BM34 -> 0 | C34: =+F34+H34+J34+L34+N34+P34+R34+T34+V34+X34+Z34+AB34+AD34+AF34+AH34+AJ34+AL34+AP34+AR34+AT34+AV34+AX34+AZ34+BB34+BD34+BF34+BH34+BJ34+BL34+BN34 -> 0 | D34: =+C34/B34 -> #DIV/0!
B35: =+E35+G35+I35+K35+M35+O35+Q35+S35+U35+W35+Y35+AA35+AC35+AE35+AG35+AI35+AK35+AO35+AQ35+AS35+AU35+AW35+AY35+BA35+BC35+BE35+BG35+BI35+BK35+BM35 -> 0 | C35: =+F35+H35+J35+L35+N35+P35+R35+T35+V35+X35+Z35+AB35+AD35+AF35+AH35+AJ35+AL35+AP35+AR35+AT35+AV35+AX35+AZ35+BB35+BD35+BF35+BH35+BJ35+BL35+BN35 -> 0 | D35: =+C35/B35 -> #DIV/0!
B36: =+E36+G36+I36+K36+M36+O36+Q36+S36+U36+W36+Y36+AA36+AC36+AE36+AG36+AI36+AK36+AO36+AQ36+AS36+AU36+AW36+AY36+BA36+BC36+BE36+BG36+BI36+BK36+BM36 -> 0 | C36: =+F36+H36+J36+L36+N36+P36+R36+T36+V36+X36+Z36+AB36+AD36+AF36+AH36+AJ36+AL36+AP36+AR36+AT36+AV36+AX36+AZ36+BB36+BD36+BF36+BH36+BJ36+BL36+BN36 -> 0 | D36: =+C36/B36 -> #DIV/0!
B37: =+E37+G37+I37+K37+M37+O37+Q37+S37+U37+W37+Y37+AA37+AC37+AE37+AG37+AI37+AK37+AO37+AQ37+AS37+AU37+AW37+AY37+BA37+BC37+BE37+BG37+BI37+BK37+BM37 -> 0 | C37: =+F37+H37+J37+L37+N37+P37+R37+T37+V37+X37+Z37+AB37+AD37+AF37+AH37+AJ37+AL37+AP37+AR37+AT37+AV37+AX37+AZ37+BB37+BD37+BF37+BH37+BJ37+BL37+BN37 -> 0 | D37: =+C37/B37 -> #DIV/0!
B38: =+E38+G38+I38+K38+M38+O38+Q38+S38+U38+W38+Y38+AA38+AC38+AE38+AG38+AI38+AK38+AO38+AQ38+AS38+AU38+AW38+AY38+BA38+BC38+BE38+BG38+BI38+BK38+BM38 -> 0 | C38: =+F38+H38+J38+L38+N38+P38+R38+T38+V38+X38+Z38+AB38+AD38+AF38+AH38+AJ38+AL38+AP38+AR38+AT38+AV38+AX38+AZ38+BB38+BD38+BF38+BH38+BJ38+BL38+BN38 -> 0 | D38: =+C38/B38 -> #DIV/0!
B39: =+E39+G39+I39+K39+M39+O39+Q39+S39+U39+W39+Y39+AA39+AC39+AE39+AG39+AI39+AK39+AO39+AQ39+AS39+AU39+AW39+AY39+BA39+BC39+BE39+BG39+BI39+BK39+BM39 -> 0 | C39: =+F39+H39+J39+L39+N39+P39+R39+T39+V39+X39+Z39+AB39+AD39+AF39+AH39+AJ39+AL39+AP39+AR39+AT39+AV39+AX39+AZ39+BB39+BD39+BF39+BH39+BJ39+BL39+BN39 -> 0 | D39: =+C39/B39 -> #DIV/0!
B40: =+E40+G40+I40+K40+M40+O40+Q40+S40+U40+W40+Y40+AA40+AC40+AE40+AG40+AI40+AK40+AO40+AQ40+AS40+AU40+AW40+AY40+BA40+BC40+BE40+BG40+BI40+BK40+BM40 -> 0 | C40: =+F40+H40+J40+L40+N40+P40+R40+T40+V40+X40+Z40+AB40+AD40+AF40+AH40+AJ40+AL40+AP40+AR40+AT40+AV40+AX40+AZ40+BB40+BD40+BF40+BH40+BJ40+BL40+BN40 -> 0 | D40: =+C40/B40 -> #DIV/0!
B41: =+E41+G41+I41+K41+M41+O41+Q41+S41+U41+W41+Y41+AA41+AC41+AE41+AG41+AI41+AK41+AO41+AQ41+AS41+AU41+AW41+AY41+BA41+BC41+BE41+BG41+BI41+BK41+BM41 -> 0 | C41: =+F41+H41+J41+L41+N41+P41+R41+T41+V41+X41+Z41+AB41+AD41+AF41+AH41+AJ41+AL41+AP41+AR41+AT41+AV41+AX41+AZ41+BB41+BD41+BF41+BH41+BJ41+BL41+BN41 -> 0 | D41: =+C41/B41 -> #DIV/0!
B42: =+E42+G42+I42+K42+M42+O42+Q42+S42+U42+W42+Y42+AA42+AC42+AE42+AG42+AI42+AK42+AO42+AQ42+AS42+AU42+AW42+AY42+BA42+BC42+BE42+BG42+BI42+BK42+BM42 -> 0 | C42: =+F42+H42+J42+L42+N42+P42+R42+T42+V42+X42+Z42+AB42+AD42+AF42+AH42+AJ42+AL42+AP42+AR42+AT42+AV42+AX42+AZ42+BB42+BD42+BF42+BH42+BJ42+BL42+BN42 -> 0 | D42: =+C42/B42 -> #DIV/0!
B43: =+E43+G43+I43+K43+M43+O43+Q43+S43+U43+W43+Y43+AA43+AC43+AE43+AG43+AI43+AK43+AO43+AQ43+AS43+AU43+AW43+AY43+BA43+BC43+BE43+BG43+BI43+BK43+BM43 -> 0 | C43: =+F43+H43+J43+L43+N43+P43+R43+T43+V43+X43+Z43+AB43+AD43+AF43+AH43+AJ43+AL43+AP43+AR43+AT43+AV43+AX43+AZ43+BB43+BD43+BF43+BH43+BJ43+BL43+BN43 -> 0 | D43: =+C43/B43 -> #DIV/0!
... B49: =+E49+G49+I49+K49+M49+O49+Q49+S49+U49+W49+Y49+AA49+AC49+AE49+AG49+AI49+AK49+AO49+AQ49+AS49+AU49+AW49+AY49+BA49+BC49+BE49+BG49+BI49+BK49+BM49 -> 0 | C49: =+F49+H49+J49+L49+N49+P49+R49+T49+V49+X49+Z49+AB49+AD49+AF49+AH49+AJ49+AL49+AP49+AR49+AT49+AV49+AX49+AZ49+BB49+BD49+BF49+BH49+BJ49+BL49+BN49 -> 0 | D49: =+C49/B49 -> #DIV/0!

Sheet deshija
A1: Control de actividades diarias
A2: Labor | B2: DESHIJA
A3: Finca: | B3: =+'amarre 1'!B3 -> Las Mesas
A4: Mes | B4: =+'amarre 1'!B4
E5: Días del mes
A6: Trabajador | B6: hrs | C6: # tramos | D6: # tramos/h | E6: 1 | G6: 2 | I6: 3 | K6: 4 | M6: 5 | O6: 6 | Q6: 7 | S6: 8 | U6: 9 | W6: 10 | Y6: 11 | AA6: 12 | AC6: 13 | AE6: 14 | AG6: 15 | AI6: 16 | AK6: 17 | AM6: 18 | AO6: 19 | AQ6: 20 | AS6: 21 | AU6: 22 | AW6: 23 | AY6: 24 | BA6: 25 | BC6: 26 | BE6: 27 | BG6: 28 | BI6: 29 | BK6: 30 | BM6: 31
E7: Hrs | F7: # tramos | G7: Hrs | H7: # tramos | I7: Hrs | J7: # tramos | K7: Hrs | L7: # tramos | M7: Hrs | N7: # tramos | O7: Hrs | P7: # tramos | Q7: Hrs | R7: # tramos | S7: Hrs | T7: # tramos | U7: Hrs | V7: # tramos | W7: Hrs | X7: # tramos | Y7: Hrs | Z7: # tramos | AA7: Hrs | AB7: # tramos | AC7: Hrs | AD7: # tramos | AE7: Hrs | AF7: # tramos | AG7: Hrs | AH7: # tramos | AI7: Hrs | AJ7: # tramos | AK7: Hrs | AL7: # tramos | AM7: Hrs | AN7: # tramos | AO7: Hrs | AP7: # tramos | AQ7: Hrs | AR7: # tramos | AS7: Hrs | AT7: # tramos | AU7: Hrs | AV7: # tramos | AW7: Hrs | AX7: # tramos | AY7: Hrs | AZ7: # tramos | BA7: Hrs | BB7: # tramos | BC7: Hrs | BD7: # tramos | BE7: Hrs | BF7: # tramos | BG7: Hrs | BH7: # tramos | BI7: Hrs | BJ7: # tramos | BK7: Hrs | BL7: # tramos | BM7: Hrs | BN7: # tramos
A8: =+cosecha!A8 -> WILMER ALTAMIRANO | B8: =+E8+G8+I8+K8+M8+O8+Q8+S8+U8+W8+Y8+AA8+AC8+AE8+AG8+AI8+AK8+AO8+AQ8+AS8+AU8+AW8+AY8+BA8+BC8+BE8+BG8+BI8+BK8+BM8 -> 0 | C8: =+F8+H8+J8+L8+N8+P8+R8+T8+V8+X8+Z8+AB8+AD8+AF8+AH8+AJ8+AL8+AP8+AR8+AT8+AV8+AX8+AZ8+BB8+BD8+BF8+BH8+BJ8+BL8+BN8 -> 0 | D8: =+C8/B8 -> #DIV/0!
A9: =+cosecha!A9 -> Jefry jardín | B9: =+E9+G9+I9+K9+M9+O9+Q9+S9+U9+W9+Y9+AA9+AC9+AE9+AG9+AI9+AK9+AO9+AQ9+AS9+AU9+AW9+AY9+BA9+BC9+BE9+BG9+BI9+BK9+BM9 -> 0 | C9: =+F9+H9+J9+L9+N9+P9+R9+T9+V9+X9+Z9+AB9+AD9+AF9+AH9+AJ9+AL9+AP9+AR9+AT9+AV9+AX9+AZ9+BB9+BD9+BF9+BH9+BJ9+BL9+BN9 -> 0 | D9: =+C9/B9 -> #DIV/0!
A10: =+cosecha!A10 -> JEFRAN POLANCO | B10: =+E10+G10+I10+K10+M10+O10+Q10+S10+U10+W10+Y10+AA10+AC10+AE10+AG10+AI10+AK10+AO10+AQ10+AS10+AU10+AW10+AY10+BA10+BC10+BE10+BG10+BI10+BK10+BM10 -> 0 | C10: =+F10+H10+J10+L10+N10+P10+R10+T10+V10+X10+Z10+AB10+AD10+AF10+AH10+AJ10+AL10+AP10+AR10+AT10+AV10+AX10+AZ10+BB10+BD10+BF10+BH10+BJ10+BL10+BN10 -> 0 | D10: =+C10/B10 -> #DIV/0!
A11: =+cosecha!A11 -> JUAN FIDENCIO | B11: =+E11+G11+I11+K11+M11+O11+Q11+S11+U11+W11+Y11+AA11+AC11+AE11+AG11+AI11+AK11+AO11+AQ11+AS11+AU11+AW11+AY11+BA11+BC11+BE11+BG11+BI11+BK11+BM11 -> 0 | C11: =+F11+H11+J11+L11+N11+P11+R11+T11+V11+X11+Z11+AB11+AD11+AF11+AH11+AJ11+AL11+AP11+AR11+AT11+AV11+AX11+AZ11+BB11+BD11+BF11+BH11+BJ11+BL11+BN11 -> 0 | D11: =+C11/B11 -> #DIV/0!
A12: =+cosecha!A12 -> HECTOR DÍAS | B12: =+E12+G12+I12+K12+M12+O12+Q12+S12+U12+W12+Y12+AA12+AC12+AE12+AG12+AI12+AK12+AO12+AQ12+AS12+AU12+AW12+AY12+BA12+BC12+BE12+BG12+BI12+BK12+BM12 -> 0 | C12: =+F12+H12+J12+L12+N12+P12+R12+T12+V12+X12+Z12+AB12+AD12+AF12+AH12+AJ12+AL12+AP12+AR12+AT12+AV12+AX12+AZ12+BB12+BD12+BF12+BH12+BJ12+BL12+BN12 -> 0 | D12: =+C12/B12 -> #DIV/0!
A13: =+cosecha!A13 -> MAYNOR AGUILAR | B13: =+E13+G13+I13+K13+M13+O13+Q13+S13+U13+W13+Y13+AA13+AC13+AE13+AG13+AI13+AK13+AO13+AQ13+AS13+AU13+AW13+AY13+BA13+BC13+BE13+BG13+BI13+BK13+BM13 -> 0 | C13: =+F13+H13+J13+L13+N13+P13+R13+T13+V13+X13+Z13+AB13+AD13+AF13+AH13+AJ13+AL13+AP13+AR13+AT13+AV13+AX13+AZ13+BB13+BD13+BF13+BH13+BJ13+BL13+BN13 -> 0 | D13: =+C13/B13 -> #DIV/0!
A14: =+cosecha!A14 -> HAXEL ZUAREZ | B14: =+E14+G14+I14+K14+M14+O14+Q14+S14+U14+W14+Y14+AA14+AC14+AE14+AG14+AI14+AK14+AO14+AQ14+AS14+AU14+AW14+AY14+BA14+BC14+BE14+BG14+BI14+BK14+BM14 -> 0 | C14: =+F14+H14+J14+L14+N14+P14+R14+T14+V14+X14+Z14+AB14+AD14+AF14+AH14+AJ14+AL14+AP14+AR14+AT14+AV14+AX14+AZ14+BB14+BD14+BF14+BH14+BJ14+BL14+BN14 -> 0 | D14: =+C14/B14 -> #DIV/0!
A15: =+cosecha!A15 -> MARVEN JARQUIN | B15: =+E15+G15+I15+K15+M15+O15+Q15+S15+U15+W15+Y15+AA15+AC15+AE15+AG15+AI15+AK15+AO15+AQ15+AS15+AU15+AW15+AY15+BA15+BC15+BE15+BG15+BI15+BK15+BM15 -> 0 | C15: =+F15+H15+J15+L15+N15+P15+R15+T15+V15+X15+Z15+AB15+AD15+AF15+AH15+AJ15+AL15+AP15+AR15+AT15+AV15+AX15+AZ15+BB15+BD15+BF15+BH15+BJ15+BL15+BN15 -> 0 | D15: =+C15/B15 -> #DIV/0!
A16: =+cosecha!A16 -> OSCAR AGUILAR | B16: =+E16+G16+I16+K16+M16+O16+Q16+S16+U16+W16+Y16+AA16+AC16+AE16+AG16+AI16+AK16+AO16+AQ16+AS16+AU16+AW16+AY16+BA16+BC16+BE16+BG16+BI16+BK16+BM16 -> 0 | C16: =+F16+H16+J16+L16+N16+P16+R16+T16+V16+X16+Z16+AB16+AD16+AF16+AH16+AJ16+AL16+AP16+AR16+AT16+AV16+AX16+AZ16+BB16+BD16+BF16+BH16+BJ16+BL16+BN16 -> 0 | D16: =+C16/B16 -> #DIV/0!
A17: =+cosecha!A17 -> MARLON LOPEZ | B17: =+E17+G17+I17+K17+M17+O17+Q17+S17+U17+W17+Y17+AA17+AC17+AE17+AG17+AI17+AK17+AO17+AQ17+AS17+AU17+AW17+AY17+BA17+BC17+BE17+BG17+BI17+BK17+BM17 -> 0 | C17: =+F17+H17+J17+L17+N17+P17+R17+T17+V17+X17+Z17+AB17+AD17+AF17+AH17+AJ17+AL17+AP17+AR17+AT17+AV17+AX17+AZ17+BB17+BD17+BF17+BH17+BJ17+BL17+BN17 -> 0 | D17: =+C17/B17 -> #DIV/0!
A18: =+cosecha!A18 -> DEIVIN TERCERO | B18: =+E18+G18+I18+K18+M18+O18+Q18+S18+U18+W18+Y18+AA18+AC18+AE18+AG18+AI18+AK18+AO18+AQ18+AS18+AU18+AW18+AY18+BA18+BC18+BE18+BG18+BI18+BK18+BM18 -> 0 | C18: =+F18+H18+J18+L18+N18+P18+R18+T18+V18+X18+Z18+AB18+AD18+AF18+AH18+AJ18+AL18+AP18+AR18+AT18+AV18+AX18+AZ18+BB18+BD18+BF18+BH18+BJ18+BL18+BN18 -> 0 | D18: =+C18/B18 -> #DIV/0!
A19: =+cosecha!A19 -> ELYAZAR TERCERO | B19: =+E19+G19+I19+K19+M19+O19+Q19+S19+U19+W19+Y19+AA19+AC19+AE19+AG19+AI19+AK19+AO19+AQ19+AS19+AU19+AW19+AY19+BA19+BC19+BE19+BG19+BI19+BK19+BM19 -> 0 | C19: =+F19+H19+J19+L19+N19+P19+R19+T19+V19+X19+Z19+AB19+AD19+AF19+AH19+AJ19+AL19+AP19+AR19+AT19+AV19+AX19+AZ19+BB19+BD19+BF19+BH19+BJ19+BL19+BN19 -> 0 | D19: =+C19/B19 -> #DIV/0!
... A30: =+cosecha!A30 | B30: =+E30+G30+I30+K30+M30+O30+Q30+S30+U30+W30+Y30+AA30+AC30+AE30+AG30+AI30+AK30+AO30+AQ30+AS30+AU30+AW30+AY30+BA30+BC30+BE30+BG30+BI30+BK30+BM30 -> 0 | C30: =+F30+H30+J30+L30+N30+P30+R30+T30+V30+X30+Z30+AB30+AD30+AF30+AH30+AJ30+AL30+AP30+AR30+AT30+AV30+AX30+AZ30+BB30+BD30+BF30+BH30+BJ30+BL30+BN30 -> 0 | D30: =+C30/B30 -> #DIV/0!
A31: =+cosecha!A33 | B31: =+E31+G31+I31+K31+M31+O31+Q31+S31+U31+W31+Y31+AA31+AC31+AE31+AG31+AI31+AK31+AO31+AQ31+AS31+AU31+AW31+AY31+BA31+BC31+BE31+BG31+BI31+BK31+BM31 -> 0 | C31: =+F31+H31+J31+L31+N31+P31+R31+T31+V31+X31+Z31+AB31+AD31+AF31+AH31+AJ31+AL31+AP31+AR31+AT31+AV31+AX31+AZ31+BB31+BD31+BF31+BH31+BJ31+BL31+BN31 -> 0 | D31: =+C31/B31 -> #DIV/0!
B32: =+E32+G32+I32+K32+M32+O32+Q32+S32+U32+W32+Y32+AA32+AC32+AE32+AG32+AI32+AK32+AO32+AQ32+AS32+AU32+AW32+AY32+BA32+BC32+BE32+BG32+BI32+BK32+BM32 -> 0 | C32: =+F32+H32+J32+L32+N32+P32+R32+T32+V32+X32+Z32+AB32+AD32+AF32+AH32+AJ32+AL32+AP32+AR32+AT32+AV32+AX32+AZ32+BB32+BD32+BF32+BH32+BJ32+BL32+BN32 -> 0 | D32: =+C32/B32 -> #DIV/0!
B33: =+E33+G33+I33+K33+M33+O33+Q33+S33+U33+W33+Y33+AA33+AC33+AE33+AG33+AI33+AK33+AO33+AQ33+AS33+AU33+AW33+AY33+BA33+BC33+BE33+BG33+BI33+BK33+BM33 -> 0 | C33: =+F33+H33+J33+L33+N33+P33+R33+T33+V33+X33+Z33+AB33+AD33+AF33+AH33+AJ33+AL33+AP33+AR33+AT33+AV33+AX33+AZ33+BB33+BD33+BF33+BH33+BJ33+BL33+BN33 -> 0 | D33: =+C33/B33 -> #DIV/0!
B34: =+E34+G34+I34+K34+M34+O34+Q34+S34+U34+W34+Y34+AA34+AC34+AE34+AG34+AI34+AK34+AO34+AQ34+AS34+AU34+AW34+AY34+BA34+BC34+BE34+BG34+BI34+BK34+BM34 -> 0 | C34: =+F34+H34+J34+L34+N34+P34+R34+T34+V34+X34+Z34+AB34+AD34+AF34+AH34+AJ34+AL34+AP34+AR34+AT34+AV34+AX34+AZ34+BB34+BD34+BF34+BH34+BJ34+BL34+BN34 -> 0 | D34: =+C34/B34 -> #DIV/0!
B35: =+E35+G35+I35+K35+M35+O35+Q35+S35+U35+W35+Y35+AA35+AC35+AE35+AG35+AI35+AK35+AO35+AQ35+AS35+AU35+AW35+AY35+BA35+BC35+BE35+BG35+BI35+BK35+BM35 -> 0 | C35: =+F35+H35+J35+L35+N35+P35+R35+T35+V35+X35+Z35+AB35+AD35+AF35+AH35+AJ35+AL35+AP35+AR35+AT35+AV35+AX35+AZ35+BB35+BD35+BF35+BH35+BJ35+BL35+BN35 -> 0 | D35: =+C35/B35 -> #DIV/0!
B36: =+E36+G36+I36+K36+M36+O36+Q36+S36+U36+W36+Y36+AA36+AC36+AE36+AG36+AI36+AK36+AO36+AQ36+AS36+AU36+AW36+AY36+BA36+BC36+BE36+BG36+BI36+BK36+BM36 -> 0 | C36: =+F36+H36+J36+L36+N36+P36+R36+T36+V36+X36+Z36+AB36+AD36+AF36+AH36+AJ36+AL36+AP36+AR36+AT36+AV36+AX36+AZ36+BB36+BD36+BF36+BH36+BJ36+BL36+BN36 -> 0 | D36: =+C36/B36 -> #DIV/0!
B37: =+E37+G37+I37+K37+M37+O37+Q37+S37+U37+W37+Y37+AA37+AC37+AE37+AG37+AI37+AK37+AO37+AQ37+AS37+AU37+AW37+AY37+BA37+BC37+BE37+BG37+BI37+BK37+BM37 -> 0 | C37: =+F37+H37+J37+L37+N37+P37+R37+T37+V37+X37+Z37+AB37+AD37+AF37+AH37+AJ37+AL37+AP37+AR37+AT37+AV37+AX37+AZ37+BB37+BD37+BF37+BH37+BJ37+BL37+BN37 -> 0 | D37: =+C37/B37 -> #DIV/0!
B38: =+E38+G38+I38+K38+M38+O38+Q38+S38+U38+W38+Y38+AA38+AC38+AE38+AG38+AI38+AK38+AO38+AQ38+AS38+AU38+AW38+AY38+BA38+BC38+BE38+BG38+BI38+BK38+BM38 -> 0 | C38: =+F38+H38+J38+L38+N38+P38+R38+T38+V38+X38+Z38+AB38+AD38+AF38+AH38+AJ38+AL38+AP38+AR38+AT38+AV38+AX38+AZ38+BB38+BD38+BF38+BH38+BJ38+BL38+BN38 -> 0 | D38: =+C38/B38 -> #DIV/0!
B39: =+E39+G39+I39+K39+M39+O39+Q39+S39+U39+W39+Y39+AA39+AC39+AE39+AG39+AI39+AK39+AO39+AQ39+AS39+AU39+AW39+AY39+BA39+BC39+BE39+BG39+BI39+BK39+BM39 -> 0 | C39: =+F39+H39+J39+L39+N39+P39+R39+T39+V39+X39+Z39+AB39+AD39+AF39+AH39+AJ39+AL39+AP39+AR39+AT39+AV39+AX39+AZ39+BB39+BD39+BF39+BH39+BJ39+BL39+BN39 -> 0 | D39: =+C39/B39 -> #DIV/0!
B40: =+E40+G40+I40+K40+M40+O40+Q40+S40+U40+W40+Y40+AA40+AC40+AE40+AG40+AI40+AK40+AO40+AQ40+AS40+AU40+AW40+AY40+BA40+BC40+BE40+BG40+BI40+BK40+BM40 -> 0 | C40: =+F40+H40+J40+L40+N40+P40+R40+T40+V40+X40+Z40+AB40+AD40+AF40+AH40+AJ40+AL40+AP40+AR40+AT40+AV40+AX40+AZ40+BB40+BD40+BF40+BH40+BJ40+BL40+BN40 -> 0 | D40: =+C40/B40 -> #DIV/0!
B41: =+E41+G41+I41+K41+M41+O41+Q41+S41+U41+W41+Y41+AA41+AC41+AE41+AG41+AI41+AK41+AO41+AQ41+AS41+AU41+AW41+AY41+BA41+BC41+BE41+BG41+BI41+BK41+BM41 -> 0 | C41: =+F41+H41+J41+L41+N41+P41+R41+T41+V41+X41+Z41+AB41+AD41+AF41+AH41+AJ41+AL41+AP41+AR41+AT41+AV41+AX41+AZ41+BB41+BD41+BF41+BH41+BJ41+BL41+BN41 -> 0 | D41: =+C41/B41 -> #DIV/0!
